
Watching for file changes with StatReloader
Страница index вызвана 00:00:00
"GET / HTTP/1.1" 200 96
Страница about вызвана 00:00:00
"GET /about/ HTTP/1.1" 200 91
C:\Users\Lex\Desktop\djangoProject_1\myapp_1\views.py changed, reloading.
C:\Users\Lex\Desktop\djangoProject_1\myapp_1\views.py changed, reloading.
Watching for file changes with StatReloader
Watching for file changes with StatReloader
Watching for file changes with StatReloader
Страница index вызвана 2023-08-25 01:22:54.382375
"GET / HTTP/1.1" 200 96
Страница about вызвана 2023-08-25 01:23:01.560401
"GET /about/ HTTP/1.1" 200 91
C:\Users\Lex\Desktop\djangoProject_1\myapp_1\urls.py changed, reloading.
Watching for file changes with StatReloader
Watching for file changes with StatReloader
Страница index вызвана 2023-08-27 18:59:48.611764
"GET / HTTP/1.1" 200 96
Not Found: /favicon.ico
- Broken pipe from ('127.0.0.1', 50811)
Страница about вызвана 2023-08-27 18:59:56.981318
"GET /about/ HTTP/1.1" 200 91
C:\Users\Lex\Desktop\djangoProject1_1\Django_Project_1\myapp_1\models.py changed, reloading.
Watching for file changes with StatReloader
C:\Users\Lex\Desktop\djangoProject1_1\Django_Project_1\manage.py changed, reloading.
Watching for file changes with StatReloader
Watching for file changes with StatReloader
Страница index вызвана 2023-08-27 19:47:35.909125
"GET / HTTP/1.1" 200 96
Not Found: /docs
"GET /docs HTTP/1.1" 404 2426
Watching for file changes with StatReloader
Страница index вызвана 2023-08-30 22:54:39.145919
Internal Server Error: /
Traceback (most recent call last):
  File "C:\Users\Lex\Desktop\djangoProject1_1\venv\lib\site-packages\django\core\handlers\exception.py", line 55, in inner
    response = get_response(request)
  File "C:\Users\Lex\Desktop\djangoProject1_1\venv\lib\site-packages\django\core\handlers\base.py", line 197, in _get_response
    response = wrapped_callback(request, *callback_args, **callback_kwargs)
  File "C:\Users\Lex\Desktop\djangoProject1_1\Django_Project_1\myapp_1\views.py", line 21, in index
    return render(request, '/base.html')
  File "C:\Users\Lex\Desktop\djangoProject1_1\venv\lib\site-packages\django\shortcuts.py", line 24, in render
    content = loader.render_to_string(template_name, context, request, using=using)
  File "C:\Users\Lex\Desktop\djangoProject1_1\venv\lib\site-packages\django\template\loader.py", line 61, in render_to_string
    template = get_template(template_name, using=using)
  File "C:\Users\Lex\Desktop\djangoProject1_1\venv\lib\site-packages\django\template\loader.py", line 19, in get_template
    raise TemplateDoesNotExist(template_name, chain=chain)
django.template.exceptions.TemplateDoesNotExist: /base.html
"GET / HTTP/1.1" 500 82166
C:\Users\Lex\Desktop\djangoProject1_1\Django_Project_1\myapp_1\views.py changed, reloading.
Watching for file changes with StatReloader
Страница index вызвана 2023-08-30 22:58:14.937224
"GET / HTTP/1.1" 200 8036
Not Found: /style.css
"GET /style.css HTTP/1.1" 404 2213
Страница index вызвана 2023-08-30 22:59:20.873590
"GET / HTTP/1.1" 200 8042
"GET /static/style.css HTTP/1.1" 404 1786
Страница index вызвана 2023-08-30 22:59:22.834610
"GET / HTTP/1.1" 200 8042
"GET /static/style.css HTTP/1.1" 404 1786
Страница index вызвана 2023-08-30 22:59:23.497725
"GET / HTTP/1.1" 200 8042
"GET /static/style.css HTTP/1.1" 404 1786
Watching for file changes with StatReloader
C:\Users\Lex\Desktop\djangoProject1_1\Django_Project_1\myapp_1\models.py changed, reloading.
Watching for file changes with StatReloader
Страница index вызвана 2023-08-30 23:02:02.066883
"GET / HTTP/1.1" 200 8097
Страница index вызвана 2023-08-30 23:02:04.734491
"GET / HTTP/1.1" 200 8097
Страница index вызвана 2023-08-30 23:02:05.397115
"GET / HTTP/1.1" 200 8097
Страница index вызвана 2023-08-30 23:02:05.933275
"GET / HTTP/1.1" 200 8097
Страница index вызвана 2023-08-30 23:10:56.197275
"GET / HTTP/1.1" 200 8042
"GET /static/style.css HTTP/1.1" 404 1786
Страница index вызвана 2023-08-30 23:10:58.462000
"GET / HTTP/1.1" 200 8042
"GET /static/style.css HTTP/1.1" 404 1786
Страница index вызвана 2023-08-30 23:10:59.172981
"GET / HTTP/1.1" 200 8042
"GET /static/style.css HTTP/1.1" 404 1786
Страница index вызвана 2023-08-30 23:10:59.519680
"GET / HTTP/1.1" 200 8042
"GET /static/style.css HTTP/1.1" 404 1786
Страница index вызвана 2023-08-30 23:10:59.756482
"GET / HTTP/1.1" 200 8042
"GET /static/style.css HTTP/1.1" 404 1786
Страница index вызвана 2023-08-30 23:10:59.961572
"GET / HTTP/1.1" 200 8042
"GET /static/style.css HTTP/1.1" 404 1786
Watching for file changes with StatReloader
Страница index вызвана 2023-08-30 23:11:21.884388
"GET / HTTP/1.1" 200 8042
"GET /static/style.css HTTP/1.1" 404 1786
Страница index вызвана 2023-08-30 23:11:56.115800
"GET / HTTP/1.1" 200 8036
Not Found: /style.css
"GET /style.css HTTP/1.1" 404 2213
Страница index вызвана 2023-08-30 23:11:56.820419
"GET / HTTP/1.1" 200 8036
Not Found: /style.css
"GET /style.css HTTP/1.1" 404 2213
C:\Users\Lex\Desktop\djangoProject1_1\Django_Project_1\djangoProject_1\settings.py changed, reloading.
Watching for file changes with StatReloader
Страница index вызвана 2023-08-30 23:18:32.798011
"GET / HTTP/1.1" 200 8070
Not Found: /css/style.css
"GET /css/style.css HTTP/1.1" 404 2225
Страница index вызвана 2023-08-30 23:18:35.379147
"GET / HTTP/1.1" 200 8070
Not Found: /css/style.css
"GET /css/style.css HTTP/1.1" 404 2225
Страница index вызвана 2023-08-30 23:18:36.039840
"GET / HTTP/1.1" 200 8070
Not Found: /css/style.css
"GET /css/style.css HTTP/1.1" 404 2225
Страница index вызвана 2023-08-30 23:18:36.325502
"GET / HTTP/1.1" 200 8070
Not Found: /css/style.css
"GET /css/style.css HTTP/1.1" 404 2225
Страница index вызвана 2023-08-30 23:18:36.545723
"GET / HTTP/1.1" 200 8070
Not Found: /css/style.css
"GET /css/style.css HTTP/1.1" 404 2225
Страница index вызвана 2023-08-30 23:18:36.766435
"GET / HTTP/1.1" 200 8070
Not Found: /css/style.css
"GET /css/style.css HTTP/1.1" 404 2225
Страница index вызвана 2023-08-30 23:18:37.019376
"GET / HTTP/1.1" 200 8070
Not Found: /css/style.css
"GET /css/style.css HTTP/1.1" 404 2225
Страница index вызвана 2023-08-30 23:18:37.492519
"GET / HTTP/1.1" 200 8070
Not Found: /css/style.css
"GET /css/style.css HTTP/1.1" 404 2225
Страница index вызвана 2023-08-30 23:18:37.728879
"GET / HTTP/1.1" 200 8070
Not Found: /css/style.css
"GET /css/style.css HTTP/1.1" 404 2225
Страница index вызвана 2023-08-30 23:18:37.933969
"GET / HTTP/1.1" 200 8070
Not Found: /css/style.css
"GET /css/style.css HTTP/1.1" 404 2225
Страница index вызвана 2023-08-30 23:18:38.161027
"GET / HTTP/1.1" 200 8070
Not Found: /css/style.css
"GET /css/style.css HTTP/1.1" 404 2225
Страница index вызвана 2023-08-30 23:18:38.398808
"GET / HTTP/1.1" 200 8070
Not Found: /css/style.css
"GET /css/style.css HTTP/1.1" 404 2225
Страница index вызвана 2023-08-30 23:18:38.603893
"GET / HTTP/1.1" 200 8070
Not Found: /css/style.css
"GET /css/style.css HTTP/1.1" 404 2225
Страница index вызвана 2023-08-30 23:18:38.825118
"GET / HTTP/1.1" 200 8070
Not Found: /css/style.css
"GET /css/style.css HTTP/1.1" 404 2225
Страница index вызвана 2023-08-30 23:18:39.061458
"GET / HTTP/1.1" 200 8070
Not Found: /css/style.css
"GET /css/style.css HTTP/1.1" 404 2225
Страница index вызвана 2023-08-30 23:18:39.518989
"GET / HTTP/1.1" 200 8070
Not Found: /css/style.css
"GET /css/style.css HTTP/1.1" 404 2225
Страница index вызвана 2023-08-30 23:18:39.739705
"GET / HTTP/1.1" 200 8070
Not Found: /css/style.css
"GET /css/style.css HTTP/1.1" 404 2225
Страница index вызвана 2023-08-30 23:18:39.944806
"GET / HTTP/1.1" 200 8070
Not Found: /css/style.css
"GET /css/style.css HTTP/1.1" 404 2225
Страница index вызвана 2023-08-30 23:18:40.323717
"GET / HTTP/1.1" 200 8070
Not Found: /css/style.css
"GET /css/style.css HTTP/1.1" 404 2225
Страница index вызвана 2023-08-30 23:18:40.812482
"GET / HTTP/1.1" 200 8070
Not Found: /css/style.css
"GET /css/style.css HTTP/1.1" 404 2225
Страница index вызвана 2023-08-30 23:18:41.018570
"GET / HTTP/1.1" 200 8070
Not Found: /css/style.css
"GET /css/style.css HTTP/1.1" 404 2225
Страница index вызвана 2023-08-30 23:18:41.223652
"GET / HTTP/1.1" 200 8070
Not Found: /css/style.css
"GET /css/style.css HTTP/1.1" 404 2225
Страница index вызвана 2023-08-30 23:18:41.428251
"GET / HTTP/1.1" 200 8070
Not Found: /css/style.css
"GET /css/style.css HTTP/1.1" 404 2225
C:\Users\Lex\Desktop\djangoProject1_1\Django_Project_1\djangoProject_1\settings.py changed, reloading.
Watching for file changes with StatReloader
C:\Users\Lex\Desktop\djangoProject1_1\Django_Project_1\djangoProject_1\settings.py changed, reloading.
Watching for file changes with StatReloader
Страница index вызвана 2023-08-30 23:27:41.865571
"GET / HTTP/1.1" 200 8052
"GET /static/static/style.css HTTP/1.1" 404 1807
Страница index вызвана 2023-08-30 23:27:44.002257
"GET / HTTP/1.1" 200 8052
"GET /static/static/style.css HTTP/1.1" 404 1807
Страница index вызвана 2023-08-30 23:27:44.602382
"GET / HTTP/1.1" 200 8052
"GET /static/static/style.css HTTP/1.1" 404 1807
Страница index вызвана 2023-08-30 23:27:44.870952
"GET / HTTP/1.1" 200 8052
"GET /static/static/style.css HTTP/1.1" 404 1807
Страница index вызвана 2023-08-30 23:27:45.066510
"GET / HTTP/1.1" 200 8052
"GET /static/static/style.css HTTP/1.1" 404 1807
Страница index вызвана 2023-08-30 23:27:45.271846
"GET / HTTP/1.1" 200 8052
"GET /static/static/style.css HTTP/1.1" 404 1807
Страница index вызвана 2023-08-30 23:27:45.476941
"GET / HTTP/1.1" 200 8052
"GET /static/static/style.css HTTP/1.1" 404 1807
Страница index вызвана 2023-08-30 23:27:45.645373
"GET / HTTP/1.1" 200 8052
"GET /static/static/style.css HTTP/1.1" 404 1807
Страница index вызвана 2023-08-30 23:32:46.459698
"GET / HTTP/1.1" 200 8053
"GET /static/static/style.css HTTP/1.1" 404 1807
Страница index вызвана 2023-08-30 23:32:47.156989
"GET / HTTP/1.1" 200 8053
"GET /static/static/style.css HTTP/1.1" 404 1807
Watching for file changes with StatReloader
Страница index вызвана 2023-08-30 23:32:59.783396
"GET / HTTP/1.1" 200 8053
"GET /static/static/style.css HTTP/1.1" 404 1807
Not Found: /user_form/
"GET /user_form/ HTTP/1.1" 404 2216
C:\Users\Lex\Desktop\djangoProject1_1\Django_Project_1\djangoProject_1\settings.py changed, reloading.
Watching for file changes with StatReloader
Страница index вызвана 2023-08-30 23:35:40.218928
"GET / HTTP/1.1" 200 8069
"GET /Django_Project_1/static/static/style.css HTTP/1.1" 404 1841
Страница index вызвана 2023-08-30 23:35:42.766881
"GET / HTTP/1.1" 200 8069
"GET /Django_Project_1/static/static/style.css HTTP/1.1" 404 1841
C:\Users\Lex\Desktop\djangoProject1_1\Django_Project_1\djangoProject_1\settings.py changed, reloading.
Watching for file changes with StatReloader
C:\Users\Lex\Desktop\djangoProject1_1\Django_Project_1\djangoProject_1\settings.py changed, reloading.
Watching for file changes with StatReloader
Страница index вызвана 2023-08-30 23:44:26.842556
"GET / HTTP/1.1" 200 8090
"GET /static/Django_Project_1/static/style.css HTTP/1.1" 404 1858
Страница index вызвана 2023-08-30 23:44:29.125014
"GET / HTTP/1.1" 200 8090
"GET /static/Django_Project_1/static/style.css HTTP/1.1" 404 1858
Not Found: /outerwear/
"GET /outerwear/ HTTP/1.1" 404 2216
C:\Users\Lex\Desktop\djangoProject1_1\Django_Project_1\djangoProject_1\settings.py changed, reloading.
Watching for file changes with StatReloader
C:\Users\Lex\Desktop\djangoProject1_1\Django_Project_1\myapp_1\views.py changed, reloading.
Watching for file changes with StatReloader
C:\Users\Lex\Desktop\djangoProject1_1\Django_Project_1\myapp_1\views.py changed, reloading.
Watching for file changes with StatReloader
Watching for file changes with StatReloader
Watching for file changes with StatReloader
Watching for file changes with StatReloader
C:\Users\Lex\Desktop\djangoProject1_1\Django_Project_1\myapp_1\views.py changed, reloading.
Watching for file changes with StatReloader
C:\Users\Lex\Desktop\djangoProject1_1\Django_Project_1\myapp_1\views.py changed, reloading.
Watching for file changes with StatReloader
C:\Users\Lex\Desktop\djangoProject1_1\Django_Project_1\myapp_1\views.py changed, reloading.
Watching for file changes with StatReloader
C:\Users\Lex\Desktop\djangoProject1_1\Django_Project_1\myapp_1\views.py changed, reloading.
Watching for file changes with StatReloader
C:\Users\Lex\Desktop\djangoProject1_1\Django_Project_1\myapp_1\views.py changed, reloading.
Watching for file changes with StatReloader
C:\Users\Lex\Desktop\djangoProject1_1\Django_Project_1\myapp_1\views.py changed, reloading.
Watching for file changes with StatReloader
Страница index вызвана 2023-08-31 02:38:43.247505
"GET / HTTP/1.1" 200 8086
"GET /static/Django_Project_1/static/style.css HTTP/1.1" 404 1858
Страница index вызвана 2023-08-31 02:39:12.873753
"GET / HTTP/1.1" 200 8086
"GET /static/Django_Project_1/static/style.css HTTP/1.1" 404 1858
C:\Users\Lex\Desktop\djangoProject1_1\Django_Project_1\myapp_1\views.py changed, reloading.
Watching for file changes with StatReloader
C:\Users\Lex\Desktop\djangoProject1_1\Django_Project_1\myapp_1\views.py changed, reloading.
Watching for file changes with StatReloader
C:\Users\Lex\Desktop\djangoProject1_1\Django_Project_1\myapp_1\views.py changed, reloading.
Watching for file changes with StatReloader
C:\Users\Lex\Desktop\djangoProject1_1\Django_Project_1\myapp_1\views.py changed, reloading.
Watching for file changes with StatReloader
Watching for file changes with StatReloader
Watching for file changes with StatReloader
C:\Users\Lex\Desktop\djangoProject1_1\Django_Project_1\myapp_1\views.py changed, reloading.
Watching for file changes with StatReloader
C:\Users\Lex\Desktop\djangoProject1_1\Django_Project_1\myapp_1\views.py changed, reloading.
Watching for file changes with StatReloader
Watching for file changes with StatReloader
Watching for file changes with StatReloader
Watching for file changes with StatReloader
Страница index вызвана 2023-09-01 05:07:02.432719
"GET / HTTP/1.1" 200 8086
"GET /static/Django_Project_1/static/style.css HTTP/1.1" 404 1858
Watching for file changes with StatReloader
Watching for file changes with StatReloader
Страница index вызвана 2023-09-02 12:45:12.407907
"GET / HTTP/1.1" 200 8086
"GET /static/Django_Project_1/static/style.css HTTP/1.1" 404 1858
Not Found: /favicon.ico
"GET /favicon.ico HTTP/1.1" 404 2219
C:\Users\Lex\Desktop\djangoProject1_1\Django_Project_1\myapp_1\views.py changed, reloading.
Watching for file changes with StatReloader
C:\Users\Lex\Desktop\djangoProject1_1\Django_Project_1\myapp_1\views.py changed, reloading.
Watching for file changes with StatReloader
C:\Users\Lex\Desktop\djangoProject1_1\Django_Project_1\myapp_1\views.py changed, reloading.
Watching for file changes with StatReloader
C:\Users\Lex\Desktop\djangoProject1_1\Django_Project_1\myapp_1\views.py changed, reloading.
Watching for file changes with StatReloader
C:\Users\Lex\Desktop\djangoProject1_1\Django_Project_1\myapp_1\views.py changed, reloading.
Watching for file changes with StatReloader
C:\Users\Lex\Desktop\djangoProject1_1\Django_Project_1\myapp_1\views.py changed, reloading.
Watching for file changes with StatReloader
C:\Users\Lex\Desktop\djangoProject1_1\Django_Project_1\myapp_1\views.py changed, reloading.
Watching for file changes with StatReloader
C:\Users\Lex\Desktop\djangoProject1_1\Django_Project_1\myapp_1\views.py changed, reloading.
Watching for file changes with StatReloader
C:\Users\Lex\Desktop\djangoProject1_1\Django_Project_1\myapp_1\views.py changed, reloading.
Watching for file changes with StatReloader
C:\Users\Lex\Desktop\djangoProject1_1\Django_Project_1\myapp_1\views.py changed, reloading.
Watching for file changes with StatReloader
C:\Users\Lex\Desktop\djangoProject1_1\Django_Project_1\myapp_1\views.py changed, reloading.
Watching for file changes with StatReloader
C:\Users\Lex\Desktop\djangoProject1_1\Django_Project_1\myapp_1\views.py changed, reloading.
Watching for file changes with StatReloader
C:\Users\Lex\Desktop\djangoProject1_1\Django_Project_1\myapp_1\views.py changed, reloading.
Watching for file changes with StatReloader
C:\Users\Lex\Desktop\djangoProject1_1\Django_Project_1\myapp_1\views.py changed, reloading.
Watching for file changes with StatReloader
C:\Users\Lex\Desktop\djangoProject1_1\Django_Project_1\myapp_1\views.py changed, reloading.
Watching for file changes with StatReloader
Watching for file changes with StatReloader
Страница index вызвана 2023-09-02 13:45:22.167165
"GET / HTTP/1.1" 200 8086
"GET /static/Django_Project_1/static/style.css HTTP/1.1" 404 1858
Not Found: /order_date
"GET /order_date HTTP/1.1" 404 2216
Not Found: /about
"GET /about HTTP/1.1" 404 2201
Not Found: /about
"GET /about HTTP/1.1" 404 2201
Not Found: /about
"GET /about HTTP/1.1" 404 2201
Not Found: /about
"GET /about HTTP/1.1" 404 2201
Not Found: /about
"GET /about HTTP/1.1" 404 2201
Not Found: /about
"GET /about HTTP/1.1" 404 2201
Not Found: /about
"GET /about HTTP/1.1" 404 2201
Not Found: /order_date
"GET /order_date HTTP/1.1" 404 2216
C:\Users\Lex\Desktop\djangoProject1_1\Django_Project_1\djangoProject_1\urls.py changed, reloading.
Watching for file changes with StatReloader
Watching for file changes with StatReloader
Watching for file changes with StatReloader
C:\Users\Lex\Desktop\djangoProject1_1\Django_Project_1\myapp_1\urls.py changed, reloading.
Watching for file changes with StatReloader
Not Found: /order_date
"GET /order_date HTTP/1.1" 404 2324
Not Found: /order_date
"GET /order_date HTTP/1.1" 404 2324
"GET /myapp_1/order_date HTTP/1.1" 301 0
Internal Server Error: /myapp_1/order_date/
Traceback (most recent call last):
  File "C:\Users\Lex\Desktop\djangoProject1_1\venv\lib\site-packages\django\core\handlers\exception.py", line 55, in inner
    response = get_response(request)
  File "C:\Users\Lex\Desktop\djangoProject1_1\venv\lib\site-packages\django\core\handlers\base.py", line 197, in _get_response
    response = wrapped_callback(request, *callback_args, **callback_kwargs)
  File "C:\Users\Lex\Desktop\djangoProject1_1\Django_Project_1\myapp_1\views.py", line 34, in client_order_date
    orders_total_count = Order.count()
AttributeError: type object 'Order' has no attribute 'count'
"GET /myapp_1/order_date/ HTTP/1.1" 500 73016
C:\Users\Lex\Desktop\djangoProject1_1\Django_Project_1\myapp_1\views.py changed, reloading.
Watching for file changes with StatReloader
Internal Server Error: /myapp_1/order_date/
Traceback (most recent call last):
  File "C:\Users\Lex\Desktop\djangoProject1_1\venv\lib\site-packages\django\core\handlers\exception.py", line 55, in inner
    response = get_response(request)
  File "C:\Users\Lex\Desktop\djangoProject1_1\venv\lib\site-packages\django\core\handlers\base.py", line 197, in _get_response
    response = wrapped_callback(request, *callback_args, **callback_kwargs)
  File "C:\Users\Lex\Desktop\djangoProject1_1\Django_Project_1\myapp_1\views.py", line 35, in client_order_date
    orders_week = Order.filter(date_added_order=today.week)
AttributeError: type object 'Order' has no attribute 'filter'
"GET /myapp_1/order_date/ HTTP/1.1" 500 72908
Internal Server Error: /myapp_1/order_date/
Traceback (most recent call last):
  File "C:\Users\Lex\Desktop\djangoProject1_1\venv\lib\site-packages\django\core\handlers\exception.py", line 55, in inner
    response = get_response(request)
  File "C:\Users\Lex\Desktop\djangoProject1_1\venv\lib\site-packages\django\core\handlers\base.py", line 197, in _get_response
    response = wrapped_callback(request, *callback_args, **callback_kwargs)
  File "C:\Users\Lex\Desktop\djangoProject1_1\Django_Project_1\myapp_1\views.py", line 35, in client_order_date
    orders_week = Order.filter(date_added_order=today.week)
AttributeError: type object 'Order' has no attribute 'filter'
"GET /myapp_1/order_date/ HTTP/1.1" 500 72908
C:\Users\Lex\Desktop\djangoProject1_1\Django_Project_1\myapp_1\views.py changed, reloading.
Watching for file changes with StatReloader
C:\Users\Lex\Desktop\djangoProject1_1\Django_Project_1\myapp_1\views.py changed, reloading.
Watching for file changes with StatReloader
Internal Server Error: /myapp_1/order_date/
Traceback (most recent call last):
  File "C:\Users\Lex\Desktop\djangoProject1_1\venv\lib\site-packages\django\core\handlers\exception.py", line 55, in inner
    response = get_response(request)
  File "C:\Users\Lex\Desktop\djangoProject1_1\venv\lib\site-packages\django\core\handlers\base.py", line 197, in _get_response
    response = wrapped_callback(request, *callback_args, **callback_kwargs)
  File "C:\Users\Lex\Desktop\djangoProject1_1\Django_Project_1\myapp_1\views.py", line 37, in client_order_date
    return  render(request, 'templates/myapp_1/all_orders_client.html', {'orders':orders, 'orders_total_count': orders_total_count, 'orders_week' : orders_week, 'order_month': order_month})
NameError: name 'orders' is not defined
"GET /myapp_1/order_date/ HTTP/1.1" 500 68641
Internal Server Error: /myapp_1/order_date/
Traceback (most recent call last):
  File "C:\Users\Lex\Desktop\djangoProject1_1\venv\lib\site-packages\django\core\handlers\exception.py", line 55, in inner
    response = get_response(request)
  File "C:\Users\Lex\Desktop\djangoProject1_1\venv\lib\site-packages\django\core\handlers\base.py", line 197, in _get_response
    response = wrapped_callback(request, *callback_args, **callback_kwargs)
  File "C:\Users\Lex\Desktop\djangoProject1_1\Django_Project_1\myapp_1\views.py", line 37, in client_order_date
    return  render(request, 'templates/myapp_1/all_orders_client.html', {'orders':orders, 'orders_total_count': orders_total_count, 'orders_week' : orders_week, 'order_month': order_month})
NameError: name 'orders' is not defined
"GET /myapp_1/order_date/ HTTP/1.1" 500 68641
Internal Server Error: /myapp_1/order_date/
Traceback (most recent call last):
  File "C:\Users\Lex\Desktop\djangoProject1_1\venv\lib\site-packages\django\core\handlers\exception.py", line 55, in inner
    response = get_response(request)
  File "C:\Users\Lex\Desktop\djangoProject1_1\venv\lib\site-packages\django\core\handlers\base.py", line 197, in _get_response
    response = wrapped_callback(request, *callback_args, **callback_kwargs)
  File "C:\Users\Lex\Desktop\djangoProject1_1\Django_Project_1\myapp_1\views.py", line 37, in client_order_date
    return  render(request, 'templates/myapp_1/all_orders_client.html', {'orders':orders, 'orders_total_count': orders_total_count, 'orders_week' : orders_week, 'order_month': order_month})
NameError: name 'orders' is not defined
"GET /myapp_1/order_date/ HTTP/1.1" 500 68641
C:\Users\Lex\Desktop\djangoProject1_1\Django_Project_1\myapp_1\views.py changed, reloading.
Watching for file changes with StatReloader
Internal Server Error: /myapp_1/order_date/
Traceback (most recent call last):
  File "C:\Users\Lex\Desktop\djangoProject1_1\venv\lib\site-packages\django\core\handlers\exception.py", line 55, in inner
    response = get_response(request)
  File "C:\Users\Lex\Desktop\djangoProject1_1\venv\lib\site-packages\django\core\handlers\base.py", line 197, in _get_response
    response = wrapped_callback(request, *callback_args, **callback_kwargs)
  File "C:\Users\Lex\Desktop\djangoProject1_1\Django_Project_1\myapp_1\views.py", line 37, in client_order_date
    return  render(request, 'templates/myapp_1/all_orders_client.html')
  File "C:\Users\Lex\Desktop\djangoProject1_1\venv\lib\site-packages\django\shortcuts.py", line 24, in render
    content = loader.render_to_string(template_name, context, request, using=using)
  File "C:\Users\Lex\Desktop\djangoProject1_1\venv\lib\site-packages\django\template\loader.py", line 61, in render_to_string
    template = get_template(template_name, using=using)
  File "C:\Users\Lex\Desktop\djangoProject1_1\venv\lib\site-packages\django\template\loader.py", line 19, in get_template
    raise TemplateDoesNotExist(template_name, chain=chain)
django.template.exceptions.TemplateDoesNotExist: templates/myapp_1/all_orders_client.html
"GET /myapp_1/order_date/ HTTP/1.1" 500 83688
Internal Server Error: /myapp_1/order_date/
Traceback (most recent call last):
  File "C:\Users\Lex\Desktop\djangoProject1_1\venv\lib\site-packages\django\core\handlers\exception.py", line 55, in inner
    response = get_response(request)
  File "C:\Users\Lex\Desktop\djangoProject1_1\venv\lib\site-packages\django\core\handlers\base.py", line 197, in _get_response
    response = wrapped_callback(request, *callback_args, **callback_kwargs)
  File "C:\Users\Lex\Desktop\djangoProject1_1\Django_Project_1\myapp_1\views.py", line 37, in client_order_date
    return  render(request, 'templates/myapp_1/all_orders_client.html')
  File "C:\Users\Lex\Desktop\djangoProject1_1\venv\lib\site-packages\django\shortcuts.py", line 24, in render
    content = loader.render_to_string(template_name, context, request, using=using)
  File "C:\Users\Lex\Desktop\djangoProject1_1\venv\lib\site-packages\django\template\loader.py", line 61, in render_to_string
    template = get_template(template_name, using=using)
  File "C:\Users\Lex\Desktop\djangoProject1_1\venv\lib\site-packages\django\template\loader.py", line 19, in get_template
    raise TemplateDoesNotExist(template_name, chain=chain)
django.template.exceptions.TemplateDoesNotExist: templates/myapp_1/all_orders_client.html
"GET /myapp_1/order_date/ HTTP/1.1" 500 83688
C:\Users\Lex\Desktop\djangoProject1_1\Django_Project_1\myapp_1\views.py changed, reloading.
Watching for file changes with StatReloader
"GET /myapp_1/order_date/ HTTP/1.1" 200 7992
"GET /myapp_1/order_date/ HTTP/1.1" 200 7992
"GET /myapp_1/order_date/ HTTP/1.1" 200 7992
"GET /myapp_1/order_date/ HTTP/1.1" 200 7992
C:\Users\Lex\Desktop\djangoProject1_1\Django_Project_1\myapp_1\views.py changed, reloading.
Watching for file changes with StatReloader
"GET /myapp_1/order_date/ HTTP/1.1" 200 7992
"GET /myapp_1/order_date/ HTTP/1.1" 200 7992
"GET /myapp_1/order_date/ HTTP/1.1" 200 7992
"GET /myapp_1/order_date/ HTTP/1.1" 200 7992
"GET /myapp_1/order_date/ HTTP/1.1" 200 7992
"GET /myapp_1/order_date/ HTTP/1.1" 200 7992
"GET /myapp_1/order_date/ HTTP/1.1" 200 7992
"GET /myapp_1/order_date/ HTTP/1.1" 200 7992
"GET /myapp_1/order_date/ HTTP/1.1" 200 7992
"GET /myapp_1/order_date/ HTTP/1.1" 200 7992
"GET /myapp_1/order_date/ HTTP/1.1" 200 7992
"GET /myapp_1/order_date/ HTTP/1.1" 200 7992
"GET /myapp_1/order_date/ HTTP/1.1" 200 7992
"GET /myapp_1/order_date/ HTTP/1.1" 200 7992
"GET /myapp_1/order_date/ HTTP/1.1" 200 7992
"GET /myapp_1/order_date/ HTTP/1.1" 200 7992
"GET /myapp_1/order_date/ HTTP/1.1" 200 7992
"GET /myapp_1/order_date/ HTTP/1.1" 200 7992
"GET /myapp_1/order_date/ HTTP/1.1" 200 7992
"GET /myapp_1/order_date/ HTTP/1.1" 200 7992
"GET /myapp_1/order_date/ HTTP/1.1" 200 7992
"GET /myapp_1/order_date/ HTTP/1.1" 200 7992
"GET /myapp_1/order_date/ HTTP/1.1" 200 7992
"GET /myapp_1/order_date/ HTTP/1.1" 200 7992
"GET /myapp_1/order_date/ HTTP/1.1" 200 7992
"GET /myapp_1/order_date/ HTTP/1.1" 200 7992
"GET /myapp_1/order_date/ HTTP/1.1" 200 7992
"GET /myapp_1/order_date/ HTTP/1.1" 200 7992
"GET /myapp_1/order_date/ HTTP/1.1" 200 7992
"GET /myapp_1/order_date/ HTTP/1.1" 200 7992
"GET /myapp_1/order_date/ HTTP/1.1" 200 7992
"GET /myapp_1/order_date/ HTTP/1.1" 200 7992
"GET /myapp_1/order_date/ HTTP/1.1" 200 7992
"GET /myapp_1/order_date/ HTTP/1.1" 200 7992
"GET /myapp_1/order_date/ HTTP/1.1" 200 7992
"GET /myapp_1/order_date/ HTTP/1.1" 200 7992
"GET /myapp_1/order_date/ HTTP/1.1" 200 7992
"GET /myapp_1/order_date/ HTTP/1.1" 200 7992
"GET /myapp_1/order_date/ HTTP/1.1" 200 7992
"GET /myapp_1/order_date/ HTTP/1.1" 200 7992
"GET /myapp_1/order_date/ HTTP/1.1" 200 7992
"GET /myapp_1/order_date/ HTTP/1.1" 200 7992
"GET /myapp_1/order_date/ HTTP/1.1" 200 7992
C:\Users\Lex\Desktop\djangoProject1_1\Django_Project_1\myapp_1\urls.py changed, reloading.
Watching for file changes with StatReloader
C:\Users\Lex\Desktop\djangoProject1_1\Django_Project_1\myapp_1\urls.py changed, reloading.
Watching for file changes with StatReloader
"GET /myapp_1/order_date/ HTTP/1.1" 200 7992
"GET /myapp_1/order_date/ HTTP/1.1" 200 7992
"GET /myapp_1/order_date/ HTTP/1.1" 200 7992
"GET /myapp_1/order_date/ HTTP/1.1" 200 7992
"GET /myapp_1/order_date/ HTTP/1.1" 200 7992
"GET /myapp_1/order_date/ HTTP/1.1" 200 7992
"GET /myapp_1/order_date/ HTTP/1.1" 200 7992
"GET /myapp_1/order_date/ HTTP/1.1" 200 7992
"GET /myapp_1/order_date/ HTTP/1.1" 200 7992
"GET /myapp_1/order_date/ HTTP/1.1" 200 7992
"GET /myapp_1/order_date/ HTTP/1.1" 200 7992
"GET /myapp_1/order_date/ HTTP/1.1" 200 7992
"GET /myapp_1/order_date/ HTTP/1.1" 200 7992
"GET /myapp_1/order_date/ HTTP/1.1" 200 7992
"GET /myapp_1/order_date/ HTTP/1.1" 200 7992
"GET /myapp_1/order_date/ HTTP/1.1" 200 7992
Watching for file changes with StatReloader
Страница index вызвана 2023-09-02 14:13:21.708210
"GET / HTTP/1.1" 200 7992
Страница index вызвана 2023-09-02 14:13:37.535112
"GET /myapp_1/ HTTP/1.1" 200 7992
"GET /myapp_1/order_date/ HTTP/1.1" 200 7992
Watching for file changes with StatReloader
Страница index вызвана 2023-09-02 14:16:46.873725
"GET / HTTP/1.1" 200 7992
Not Found: /favicon.ico
- Broken pipe from ('127.0.0.1', 53914)
"GET /myapp_1/order_date/ HTTP/1.1" 200 7992
Страница index вызвана 2023-09-02 14:16:53.443353
"GET /myapp_1/ HTTP/1.1" 200 7992
"GET /myapp_1/order_date/ HTTP/1.1" 200 7992
Not Found: /outerwear/
"GET /outerwear/ HTTP/1.1" 404 2324
Watching for file changes with StatReloader
Страница index вызвана 2023-09-02 23:15:44.211586
Internal Server Error: /
Traceback (most recent call last):
  File "C:\Users\Lex\Desktop\djangoProject1_1\venv\lib\site-packages\django\core\handlers\exception.py", line 55, in inner
    response = get_response(request)
  File "C:\Users\Lex\Desktop\djangoProject1_1\venv\lib\site-packages\django\core\handlers\base.py", line 197, in _get_response
    response = wrapped_callback(request, *callback_args, **callback_kwargs)
  File "C:\Users\Lex\Desktop\djangoProject1_1\Django_Project_1\myapp_1\views.py", line 24, in index
    return render(request, 'base.html')
  File "C:\Users\Lex\Desktop\djangoProject1_1\venv\lib\site-packages\django\shortcuts.py", line 24, in render
    content = loader.render_to_string(template_name, context, request, using=using)
  File "C:\Users\Lex\Desktop\djangoProject1_1\venv\lib\site-packages\django\template\loader.py", line 61, in render_to_string
    template = get_template(template_name, using=using)
  File "C:\Users\Lex\Desktop\djangoProject1_1\venv\lib\site-packages\django\template\loader.py", line 19, in get_template
    raise TemplateDoesNotExist(template_name, chain=chain)
django.template.exceptions.TemplateDoesNotExist: base.html
"GET / HTTP/1.1" 500 83812
C:\Users\Lex\Desktop\djangoProject1_1\Django_Project_1\djangoProject_1\urls.py changed, reloading.
Watching for file changes with StatReloader
Not Found: /
"GET / HTTP/1.1" 404 2176
Not Found: /
"GET / HTTP/1.1" 404 2176
C:\Users\Lex\Desktop\djangoProject1_1\Django_Project_1\myapp_1\views.py changed, reloading.
Watching for file changes with StatReloader
Not Found: /
"GET / HTTP/1.1" 404 2176
C:\Users\Lex\Desktop\djangoProject1_1\Django_Project_1\djangoProject_1\urls.py changed, reloading.
Watching for file changes with StatReloader
Страница index вызвана 2023-09-02 23:20:51.366662
"GET / HTTP/1.1" 200 7992
Watching for file changes with StatReloader
Страница index вызвана 2023-09-02 23:34:39.570361
"GET / HTTP/1.1" 200 8057
"GET /static/myapp_1/style.css HTTP/1.1" 200 557
"GET /order_date HTTP/1.1" 301 0
Internal Server Error: /order_date/
Traceback (most recent call last):
  File "C:\Users\Lex\Desktop\djangoProject1_1\venv\lib\site-packages\django\template\backends\django.py", line 61, in render
    return self.template.render(context)
  File "C:\Users\Lex\Desktop\djangoProject1_1\venv\lib\site-packages\django\template\base.py", line 175, in render
    return self._render(context)
  File "C:\Users\Lex\Desktop\djangoProject1_1\venv\lib\site-packages\django\template\base.py", line 167, in _render
    return self.nodelist.render(context)
  File "C:\Users\Lex\Desktop\djangoProject1_1\venv\lib\site-packages\django\template\base.py", line 1005, in render
    return SafeString("".join([node.render_annotated(context) for node in self]))
  File "C:\Users\Lex\Desktop\djangoProject1_1\venv\lib\site-packages\django\template\base.py", line 1005, in <listcomp>
    return SafeString("".join([node.render_annotated(context) for node in self]))
  File "C:\Users\Lex\Desktop\djangoProject1_1\venv\lib\site-packages\django\template\base.py", line 966, in render_annotated
    return self.render(context)
  File "C:\Users\Lex\Desktop\djangoProject1_1\venv\lib\site-packages\django\template\loader_tags.py", line 132, in render
    compiled_parent = self.get_parent(context)
  File "C:\Users\Lex\Desktop\djangoProject1_1\venv\lib\site-packages\django\template\loader_tags.py", line 129, in get_parent
    return self.find_template(parent, context)
  File "C:\Users\Lex\Desktop\djangoProject1_1\venv\lib\site-packages\django\template\loader_tags.py", line 107, in find_template
    template, origin = context.template.engine.find_template(
  File "C:\Users\Lex\Desktop\djangoProject1_1\venv\lib\site-packages\django\template\engine.py", line 161, in find_template
    raise TemplateDoesNotExist(name, tried=tried)
django.template.exceptions.TemplateDoesNotExist: base.html

The above exception was the direct cause of the following exception:

Traceback (most recent call last):
  File "C:\Users\Lex\Desktop\djangoProject1_1\venv\lib\site-packages\django\core\handlers\exception.py", line 55, in inner
    response = get_response(request)
  File "C:\Users\Lex\Desktop\djangoProject1_1\venv\lib\site-packages\django\core\handlers\base.py", line 197, in _get_response
    response = wrapped_callback(request, *callback_args, **callback_kwargs)
  File "C:\Users\Lex\Desktop\djangoProject1_1\Django_Project_1\myapp_1\views.py", line 37, in client_order_date
    return render(request, 'myapp_1/all_orders_client.html')
  File "C:\Users\Lex\Desktop\djangoProject1_1\venv\lib\site-packages\django\shortcuts.py", line 24, in render
    content = loader.render_to_string(template_name, context, request, using=using)
  File "C:\Users\Lex\Desktop\djangoProject1_1\venv\lib\site-packages\django\template\loader.py", line 62, in render_to_string
    return template.render(context, request)
  File "C:\Users\Lex\Desktop\djangoProject1_1\venv\lib\site-packages\django\template\backends\django.py", line 63, in render
    reraise(exc, self.backend)
  File "C:\Users\Lex\Desktop\djangoProject1_1\venv\lib\site-packages\django\template\backends\django.py", line 84, in reraise
    raise new from exc
django.template.exceptions.TemplateDoesNotExist: base.html
"GET /order_date/ HTTP/1.1" 500 131045
Watching for file changes with StatReloader
Страница index вызвана 2023-09-02 23:50:52.664902
"GET / HTTP/1.1" 200 8057
"GET /order_date/ HTTP/1.1" 200 8057
"GET /order_date/ HTTP/1.1" 200 8057
"GET /order_date/ HTTP/1.1" 200 8057
"GET /order_date/ HTTP/1.1" 200 8057
"GET /order_date/ HTTP/1.1" 200 7933
C:\Users\Lex\Desktop\djangoProject1_1\Django_Project_1\myapp_1\views.py changed, reloading.
Watching for file changes with StatReloader
C:\Users\Lex\Desktop\djangoProject1_1\Django_Project_1\myapp_1\views.py changed, reloading.
Watching for file changes with StatReloader
"GET /order_date/ HTTP/1.1" 200 11629
"GET /order_date/ HTTP/1.1" 200 11622
"GET /order_date/ HTTP/1.1" 200 11654
C:\Users\Lex\Desktop\djangoProject1_1\Django_Project_1\myapp_1\views.py changed, reloading.
Watching for file changes with StatReloader
Internal Server Error: /order_date/
Traceback (most recent call last):
  File "C:\Users\Lex\Desktop\djangoProject1_1\venv\lib\site-packages\django\core\handlers\exception.py", line 55, in inner
    response = get_response(request)
  File "C:\Users\Lex\Desktop\djangoProject1_1\venv\lib\site-packages\django\core\handlers\base.py", line 197, in _get_response
    response = wrapped_callback(request, *callback_args, **callback_kwargs)
  File "C:\Users\Lex\Desktop\djangoProject1_1\Django_Project_1\myapp_1\views.py", line 34, in client_order_date
    orders_total_count = Order.count()
AttributeError: type object 'Order' has no attribute 'count'
"GET /order_date/ HTTP/1.1" 500 72861
C:\Users\Lex\Desktop\djangoProject1_1\Django_Project_1\myapp_1\views.py changed, reloading.
Watching for file changes with StatReloader
C:\Users\Lex\Desktop\djangoProject1_1\Django_Project_1\myapp_1\views.py changed, reloading.
Watching for file changes with StatReloader
"GET /order_date/ HTTP/1.1" 200 11866
"GET /order_date/ HTTP/1.1" 200 11706
C:\Users\Lex\Desktop\djangoProject1_1\Django_Project_1\myapp_1\views.py changed, reloading.
Watching for file changes with StatReloader
C:\Users\Lex\Desktop\djangoProject1_1\Django_Project_1\myapp_1\views.py changed, reloading.
Watching for file changes with StatReloader
C:\Users\Lex\Desktop\djangoProject1_1\Django_Project_1\myapp_1\views.py changed, reloading.
Watching for file changes with StatReloader
"GET /order_date/ HTTP/1.1" 200 11722
Watching for file changes with StatReloader
Страница index вызвана 2023-09-03 00:23:20.162386
"GET / HTTP/1.1" 200 8057
"GET /order_date/ HTTP/1.1" 200 11722
"GET /order_date/ HTTP/1.1" 200 11722
C:\Users\Lex\Desktop\djangoProject1_1\Django_Project_1\myapp_1\views.py changed, reloading.
Watching for file changes with StatReloader
C:\Users\Lex\Desktop\djangoProject1_1\Django_Project_1\myapp_1\views.py changed, reloading.
Watching for file changes with StatReloader
C:\Users\Lex\Desktop\djangoProject1_1\Django_Project_1\myapp_1\views.py changed, reloading.
Watching for file changes with StatReloader
Internal Server Error: /order_date/
Traceback (most recent call last):
  File "C:\Users\Lex\Desktop\djangoProject1_1\venv\lib\site-packages\django\core\handlers\exception.py", line 55, in inner
    response = get_response(request)
  File "C:\Users\Lex\Desktop\djangoProject1_1\venv\lib\site-packages\django\core\handlers\base.py", line 197, in _get_response
    response = wrapped_callback(request, *callback_args, **callback_kwargs)
  File "C:\Users\Lex\Desktop\djangoProject1_1\Django_Project_1\myapp_1\views.py", line 37, in client_order_date
    order_month = Order.filter(date_added_order=today.month)
AttributeError: type object 'Order' has no attribute 'filter'
"GET /order_date/ HTTP/1.1" 500 72848
C:\Users\Lex\Desktop\djangoProject1_1\Django_Project_1\myapp_1\views.py changed, reloading.
Watching for file changes with StatReloader
Internal Server Error: /order_date/
Traceback (most recent call last):
  File "C:\Users\Lex\Desktop\djangoProject1_1\venv\lib\site-packages\django\core\handlers\exception.py", line 55, in inner
    response = get_response(request)
  File "C:\Users\Lex\Desktop\djangoProject1_1\venv\lib\site-packages\django\core\handlers\base.py", line 197, in _get_response
    response = wrapped_callback(request, *callback_args, **callback_kwargs)
  File "C:\Users\Lex\Desktop\djangoProject1_1\Django_Project_1\myapp_1\views.py", line 37, in client_order_date
    order_month = Order.objects.get(date_added_order=today.month)
  File "C:\Users\Lex\Desktop\djangoProject1_1\venv\lib\site-packages\django\db\models\manager.py", line 87, in manager_method
    return getattr(self.get_queryset(), name)(*args, **kwargs)
  File "C:\Users\Lex\Desktop\djangoProject1_1\venv\lib\site-packages\django\db\models\query.py", line 623, in get
    clone = self._chain() if self.query.combinator else self.filter(*args, **kwargs)
  File "C:\Users\Lex\Desktop\djangoProject1_1\venv\lib\site-packages\django\db\models\query.py", line 1436, in filter
    return self._filter_or_exclude(False, args, kwargs)
  File "C:\Users\Lex\Desktop\djangoProject1_1\venv\lib\site-packages\django\db\models\query.py", line 1454, in _filter_or_exclude
    clone._filter_or_exclude_inplace(negate, args, kwargs)
  File "C:\Users\Lex\Desktop\djangoProject1_1\venv\lib\site-packages\django\db\models\query.py", line 1461, in _filter_or_exclude_inplace
    self._query.add_q(Q(*args, **kwargs))
  File "C:\Users\Lex\Desktop\djangoProject1_1\venv\lib\site-packages\django\db\models\sql\query.py", line 1545, in add_q
    clause, _ = self._add_q(q_object, self.used_aliases)
  File "C:\Users\Lex\Desktop\djangoProject1_1\venv\lib\site-packages\django\db\models\sql\query.py", line 1576, in _add_q
    child_clause, needed_inner = self.build_filter(
  File "C:\Users\Lex\Desktop\djangoProject1_1\venv\lib\site-packages\django\db\models\sql\query.py", line 1491, in build_filter
    condition = self.build_lookup(lookups, col, value)
  File "C:\Users\Lex\Desktop\djangoProject1_1\venv\lib\site-packages\django\db\models\sql\query.py", line 1318, in build_lookup
    lookup = lookup_class(lhs, rhs)
  File "C:\Users\Lex\Desktop\djangoProject1_1\venv\lib\site-packages\django\db\models\lookups.py", line 27, in __init__
    self.rhs = self.get_prep_lookup()
  File "C:\Users\Lex\Desktop\djangoProject1_1\venv\lib\site-packages\django\db\models\lookups.py", line 341, in get_prep_lookup
    return super().get_prep_lookup()
  File "C:\Users\Lex\Desktop\djangoProject1_1\venv\lib\site-packages\django\db\models\lookups.py", line 85, in get_prep_lookup
    return self.lhs.output_field.get_prep_value(self.rhs)
  File "C:\Users\Lex\Desktop\djangoProject1_1\venv\lib\site-packages\django\db\models\fields\__init__.py", line 1585, in get_prep_value
    value = super().get_prep_value(value)
  File "C:\Users\Lex\Desktop\djangoProject1_1\venv\lib\site-packages\django\db\models\fields\__init__.py", line 1464, in get_prep_value
    return self.to_python(value)
  File "C:\Users\Lex\Desktop\djangoProject1_1\venv\lib\site-packages\django\db\models\fields\__init__.py", line 1546, in to_python
    parsed = parse_datetime(value)
  File "C:\Users\Lex\Desktop\djangoProject1_1\venv\lib\site-packages\django\utils\dateparse.py", line 114, in parse_datetime
    return datetime.datetime.fromisoformat(value)
TypeError: fromisoformat: argument must be str
"GET /order_date/ HTTP/1.1" 500 162395
C:\Users\Lex\Desktop\djangoProject1_1\Django_Project_1\myapp_1\models.py changed, reloading.
Watching for file changes with StatReloader
C:\Users\Lex\Desktop\djangoProject1_1\Django_Project_1\myapp_1\models.py changed, reloading.
Watching for file changes with StatReloader
Internal Server Error: /order_date/
Traceback (most recent call last):
  File "C:\Users\Lex\Desktop\djangoProject1_1\venv\lib\site-packages\django\core\handlers\exception.py", line 55, in inner
    response = get_response(request)
  File "C:\Users\Lex\Desktop\djangoProject1_1\venv\lib\site-packages\django\core\handlers\base.py", line 197, in _get_response
    response = wrapped_callback(request, *callback_args, **callback_kwargs)
  File "C:\Users\Lex\Desktop\djangoProject1_1\Django_Project_1\myapp_1\views.py", line 37, in client_order_date
    order_month = Order.objects.get(date_added_order=today.month)
  File "C:\Users\Lex\Desktop\djangoProject1_1\venv\lib\site-packages\django\db\models\manager.py", line 87, in manager_method
    return getattr(self.get_queryset(), name)(*args, **kwargs)
  File "C:\Users\Lex\Desktop\djangoProject1_1\venv\lib\site-packages\django\db\models\query.py", line 623, in get
    clone = self._chain() if self.query.combinator else self.filter(*args, **kwargs)
  File "C:\Users\Lex\Desktop\djangoProject1_1\venv\lib\site-packages\django\db\models\query.py", line 1436, in filter
    return self._filter_or_exclude(False, args, kwargs)
  File "C:\Users\Lex\Desktop\djangoProject1_1\venv\lib\site-packages\django\db\models\query.py", line 1454, in _filter_or_exclude
    clone._filter_or_exclude_inplace(negate, args, kwargs)
  File "C:\Users\Lex\Desktop\djangoProject1_1\venv\lib\site-packages\django\db\models\query.py", line 1461, in _filter_or_exclude_inplace
    self._query.add_q(Q(*args, **kwargs))
  File "C:\Users\Lex\Desktop\djangoProject1_1\venv\lib\site-packages\django\db\models\sql\query.py", line 1545, in add_q
    clause, _ = self._add_q(q_object, self.used_aliases)
  File "C:\Users\Lex\Desktop\djangoProject1_1\venv\lib\site-packages\django\db\models\sql\query.py", line 1576, in _add_q
    child_clause, needed_inner = self.build_filter(
  File "C:\Users\Lex\Desktop\djangoProject1_1\venv\lib\site-packages\django\db\models\sql\query.py", line 1491, in build_filter
    condition = self.build_lookup(lookups, col, value)
  File "C:\Users\Lex\Desktop\djangoProject1_1\venv\lib\site-packages\django\db\models\sql\query.py", line 1318, in build_lookup
    lookup = lookup_class(lhs, rhs)
  File "C:\Users\Lex\Desktop\djangoProject1_1\venv\lib\site-packages\django\db\models\lookups.py", line 27, in __init__
    self.rhs = self.get_prep_lookup()
  File "C:\Users\Lex\Desktop\djangoProject1_1\venv\lib\site-packages\django\db\models\lookups.py", line 341, in get_prep_lookup
    return super().get_prep_lookup()
  File "C:\Users\Lex\Desktop\djangoProject1_1\venv\lib\site-packages\django\db\models\lookups.py", line 85, in get_prep_lookup
    return self.lhs.output_field.get_prep_value(self.rhs)
  File "C:\Users\Lex\Desktop\djangoProject1_1\venv\lib\site-packages\django\db\models\fields\__init__.py", line 1585, in get_prep_value
    value = super().get_prep_value(value)
  File "C:\Users\Lex\Desktop\djangoProject1_1\venv\lib\site-packages\django\db\models\fields\__init__.py", line 1464, in get_prep_value
    return self.to_python(value)
  File "C:\Users\Lex\Desktop\djangoProject1_1\venv\lib\site-packages\django\db\models\fields\__init__.py", line 1546, in to_python
    parsed = parse_datetime(value)
  File "C:\Users\Lex\Desktop\djangoProject1_1\venv\lib\site-packages\django\utils\dateparse.py", line 114, in parse_datetime
    return datetime.datetime.fromisoformat(value)
TypeError: fromisoformat: argument must be str
"GET /order_date/ HTTP/1.1" 500 162395
C:\Users\Lex\Desktop\djangoProject1_1\Django_Project_1\myapp_1\models.py changed, reloading.
Watching for file changes with StatReloader
C:\Users\Lex\Desktop\djangoProject1_1\Django_Project_1\myapp_1\models.py changed, reloading.
Watching for file changes with StatReloader
Watching for file changes with StatReloader
C:\Users\Lex\Desktop\djangoProject1_1\Django_Project_1\myapp_1\models.py changed, reloading.
Watching for file changes with StatReloader
Internal Server Error: /order_date/
Traceback (most recent call last):
  File "C:\Users\Lex\Desktop\djangoProject1_1\venv\lib\site-packages\django\core\handlers\exception.py", line 55, in inner
    response = get_response(request)
  File "C:\Users\Lex\Desktop\djangoProject1_1\venv\lib\site-packages\django\core\handlers\base.py", line 197, in _get_response
    response = wrapped_callback(request, *callback_args, **callback_kwargs)
  File "C:\Users\Lex\Desktop\djangoProject1_1\Django_Project_1\myapp_1\views.py", line 37, in client_order_date
    order_month = Order.objects.get(date_added_order=today.month)
  File "C:\Users\Lex\Desktop\djangoProject1_1\venv\lib\site-packages\django\db\models\manager.py", line 87, in manager_method
    return getattr(self.get_queryset(), name)(*args, **kwargs)
  File "C:\Users\Lex\Desktop\djangoProject1_1\venv\lib\site-packages\django\db\models\query.py", line 623, in get
    clone = self._chain() if self.query.combinator else self.filter(*args, **kwargs)
  File "C:\Users\Lex\Desktop\djangoProject1_1\venv\lib\site-packages\django\db\models\query.py", line 1436, in filter
    return self._filter_or_exclude(False, args, kwargs)
  File "C:\Users\Lex\Desktop\djangoProject1_1\venv\lib\site-packages\django\db\models\query.py", line 1454, in _filter_or_exclude
    clone._filter_or_exclude_inplace(negate, args, kwargs)
  File "C:\Users\Lex\Desktop\djangoProject1_1\venv\lib\site-packages\django\db\models\query.py", line 1461, in _filter_or_exclude_inplace
    self._query.add_q(Q(*args, **kwargs))
  File "C:\Users\Lex\Desktop\djangoProject1_1\venv\lib\site-packages\django\db\models\sql\query.py", line 1545, in add_q
    clause, _ = self._add_q(q_object, self.used_aliases)
  File "C:\Users\Lex\Desktop\djangoProject1_1\venv\lib\site-packages\django\db\models\sql\query.py", line 1576, in _add_q
    child_clause, needed_inner = self.build_filter(
  File "C:\Users\Lex\Desktop\djangoProject1_1\venv\lib\site-packages\django\db\models\sql\query.py", line 1491, in build_filter
    condition = self.build_lookup(lookups, col, value)
  File "C:\Users\Lex\Desktop\djangoProject1_1\venv\lib\site-packages\django\db\models\sql\query.py", line 1318, in build_lookup
    lookup = lookup_class(lhs, rhs)
  File "C:\Users\Lex\Desktop\djangoProject1_1\venv\lib\site-packages\django\db\models\lookups.py", line 27, in __init__
    self.rhs = self.get_prep_lookup()
  File "C:\Users\Lex\Desktop\djangoProject1_1\venv\lib\site-packages\django\db\models\lookups.py", line 341, in get_prep_lookup
    return super().get_prep_lookup()
  File "C:\Users\Lex\Desktop\djangoProject1_1\venv\lib\site-packages\django\db\models\lookups.py", line 85, in get_prep_lookup
    return self.lhs.output_field.get_prep_value(self.rhs)
  File "C:\Users\Lex\Desktop\djangoProject1_1\venv\lib\site-packages\django\db\models\fields\__init__.py", line 1585, in get_prep_value
    value = super().get_prep_value(value)
  File "C:\Users\Lex\Desktop\djangoProject1_1\venv\lib\site-packages\django\db\models\fields\__init__.py", line 1464, in get_prep_value
    return self.to_python(value)
  File "C:\Users\Lex\Desktop\djangoProject1_1\venv\lib\site-packages\django\db\models\fields\__init__.py", line 1546, in to_python
    parsed = parse_datetime(value)
  File "C:\Users\Lex\Desktop\djangoProject1_1\venv\lib\site-packages\django\utils\dateparse.py", line 114, in parse_datetime
    return datetime.datetime.fromisoformat(value)
TypeError: fromisoformat: argument must be str
"GET /order_date/ HTTP/1.1" 500 162395
C:\Users\Lex\Desktop\djangoProject1_1\Django_Project_1\myapp_1\views.py changed, reloading.
Watching for file changes with StatReloader
Internal Server Error: /order_date/
Traceback (most recent call last):
  File "C:\Users\Lex\Desktop\djangoProject1_1\venv\lib\site-packages\django\core\handlers\exception.py", line 55, in inner
    response = get_response(request)
  File "C:\Users\Lex\Desktop\djangoProject1_1\venv\lib\site-packages\django\core\handlers\base.py", line 197, in _get_response
    response = wrapped_callback(request, *callback_args, **callback_kwargs)
  File "C:\Users\Lex\Desktop\djangoProject1_1\Django_Project_1\myapp_1\views.py", line 37, in client_order_date
    order_month = Order.objects.get(date_added_order=today.month)
  File "C:\Users\Lex\Desktop\djangoProject1_1\venv\lib\site-packages\django\db\models\manager.py", line 87, in manager_method
    return getattr(self.get_queryset(), name)(*args, **kwargs)
  File "C:\Users\Lex\Desktop\djangoProject1_1\venv\lib\site-packages\django\db\models\query.py", line 623, in get
    clone = self._chain() if self.query.combinator else self.filter(*args, **kwargs)
  File "C:\Users\Lex\Desktop\djangoProject1_1\venv\lib\site-packages\django\db\models\query.py", line 1436, in filter
    return self._filter_or_exclude(False, args, kwargs)
  File "C:\Users\Lex\Desktop\djangoProject1_1\venv\lib\site-packages\django\db\models\query.py", line 1454, in _filter_or_exclude
    clone._filter_or_exclude_inplace(negate, args, kwargs)
  File "C:\Users\Lex\Desktop\djangoProject1_1\venv\lib\site-packages\django\db\models\query.py", line 1461, in _filter_or_exclude_inplace
    self._query.add_q(Q(*args, **kwargs))
  File "C:\Users\Lex\Desktop\djangoProject1_1\venv\lib\site-packages\django\db\models\sql\query.py", line 1545, in add_q
    clause, _ = self._add_q(q_object, self.used_aliases)
  File "C:\Users\Lex\Desktop\djangoProject1_1\venv\lib\site-packages\django\db\models\sql\query.py", line 1576, in _add_q
    child_clause, needed_inner = self.build_filter(
  File "C:\Users\Lex\Desktop\djangoProject1_1\venv\lib\site-packages\django\db\models\sql\query.py", line 1491, in build_filter
    condition = self.build_lookup(lookups, col, value)
  File "C:\Users\Lex\Desktop\djangoProject1_1\venv\lib\site-packages\django\db\models\sql\query.py", line 1318, in build_lookup
    lookup = lookup_class(lhs, rhs)
  File "C:\Users\Lex\Desktop\djangoProject1_1\venv\lib\site-packages\django\db\models\lookups.py", line 27, in __init__
    self.rhs = self.get_prep_lookup()
  File "C:\Users\Lex\Desktop\djangoProject1_1\venv\lib\site-packages\django\db\models\lookups.py", line 341, in get_prep_lookup
    return super().get_prep_lookup()
  File "C:\Users\Lex\Desktop\djangoProject1_1\venv\lib\site-packages\django\db\models\lookups.py", line 85, in get_prep_lookup
    return self.lhs.output_field.get_prep_value(self.rhs)
  File "C:\Users\Lex\Desktop\djangoProject1_1\venv\lib\site-packages\django\db\models\fields\__init__.py", line 1585, in get_prep_value
    value = super().get_prep_value(value)
  File "C:\Users\Lex\Desktop\djangoProject1_1\venv\lib\site-packages\django\db\models\fields\__init__.py", line 1464, in get_prep_value
    return self.to_python(value)
  File "C:\Users\Lex\Desktop\djangoProject1_1\venv\lib\site-packages\django\db\models\fields\__init__.py", line 1546, in to_python
    parsed = parse_datetime(value)
  File "C:\Users\Lex\Desktop\djangoProject1_1\venv\lib\site-packages\django\utils\dateparse.py", line 114, in parse_datetime
    return datetime.datetime.fromisoformat(value)
TypeError: fromisoformat: argument must be str
"GET /order_date/ HTTP/1.1" 500 162400
C:\Users\Lex\Desktop\djangoProject1_1\Django_Project_1\myapp_1\views.py changed, reloading.
Watching for file changes with StatReloader
C:\Users\Lex\Desktop\djangoProject1_1\Django_Project_1\myapp_1\models.py changed, reloading.
Watching for file changes with StatReloader
Страница index вызвана 2023-09-03 01:07:02.758110
"GET / HTTP/1.1" 200 8057
Internal Server Error: /order_date/
Traceback (most recent call last):
  File "C:\Users\Lex\Desktop\djangoProject1_1\venv\lib\site-packages\django\core\handlers\exception.py", line 55, in inner
    response = get_response(request)
  File "C:\Users\Lex\Desktop\djangoProject1_1\venv\lib\site-packages\django\core\handlers\base.py", line 197, in _get_response
    response = wrapped_callback(request, *callback_args, **callback_kwargs)
  File "C:\Users\Lex\Desktop\djangoProject1_1\Django_Project_1\myapp_1\views.py", line 37, in client_order_date
    order_month = Order.objects.get(date_added_order=today.month)
  File "C:\Users\Lex\Desktop\djangoProject1_1\venv\lib\site-packages\django\db\models\manager.py", line 87, in manager_method
    return getattr(self.get_queryset(), name)(*args, **kwargs)
  File "C:\Users\Lex\Desktop\djangoProject1_1\venv\lib\site-packages\django\db\models\query.py", line 623, in get
    clone = self._chain() if self.query.combinator else self.filter(*args, **kwargs)
  File "C:\Users\Lex\Desktop\djangoProject1_1\venv\lib\site-packages\django\db\models\query.py", line 1436, in filter
    return self._filter_or_exclude(False, args, kwargs)
  File "C:\Users\Lex\Desktop\djangoProject1_1\venv\lib\site-packages\django\db\models\query.py", line 1454, in _filter_or_exclude
    clone._filter_or_exclude_inplace(negate, args, kwargs)
  File "C:\Users\Lex\Desktop\djangoProject1_1\venv\lib\site-packages\django\db\models\query.py", line 1461, in _filter_or_exclude_inplace
    self._query.add_q(Q(*args, **kwargs))
  File "C:\Users\Lex\Desktop\djangoProject1_1\venv\lib\site-packages\django\db\models\sql\query.py", line 1545, in add_q
    clause, _ = self._add_q(q_object, self.used_aliases)
  File "C:\Users\Lex\Desktop\djangoProject1_1\venv\lib\site-packages\django\db\models\sql\query.py", line 1576, in _add_q
    child_clause, needed_inner = self.build_filter(
  File "C:\Users\Lex\Desktop\djangoProject1_1\venv\lib\site-packages\django\db\models\sql\query.py", line 1491, in build_filter
    condition = self.build_lookup(lookups, col, value)
  File "C:\Users\Lex\Desktop\djangoProject1_1\venv\lib\site-packages\django\db\models\sql\query.py", line 1318, in build_lookup
    lookup = lookup_class(lhs, rhs)
  File "C:\Users\Lex\Desktop\djangoProject1_1\venv\lib\site-packages\django\db\models\lookups.py", line 27, in __init__
    self.rhs = self.get_prep_lookup()
  File "C:\Users\Lex\Desktop\djangoProject1_1\venv\lib\site-packages\django\db\models\lookups.py", line 341, in get_prep_lookup
    return super().get_prep_lookup()
  File "C:\Users\Lex\Desktop\djangoProject1_1\venv\lib\site-packages\django\db\models\lookups.py", line 85, in get_prep_lookup
    return self.lhs.output_field.get_prep_value(self.rhs)
  File "C:\Users\Lex\Desktop\djangoProject1_1\venv\lib\site-packages\django\db\models\fields\__init__.py", line 1585, in get_prep_value
    value = super().get_prep_value(value)
  File "C:\Users\Lex\Desktop\djangoProject1_1\venv\lib\site-packages\django\db\models\fields\__init__.py", line 1464, in get_prep_value
    return self.to_python(value)
  File "C:\Users\Lex\Desktop\djangoProject1_1\venv\lib\site-packages\django\db\models\fields\__init__.py", line 1546, in to_python
    parsed = parse_datetime(value)
  File "C:\Users\Lex\Desktop\djangoProject1_1\venv\lib\site-packages\django\utils\dateparse.py", line 114, in parse_datetime
    return datetime.datetime.fromisoformat(value)
TypeError: fromisoformat: argument must be str
"GET /order_date/ HTTP/1.1" 500 140891
C:\Users\Lex\Desktop\djangoProject1_1\Django_Project_1\myapp_1\models.py changed, reloading.
Watching for file changes with StatReloader
Internal Server Error: /order_date/
Traceback (most recent call last):
  File "C:\Users\Lex\Desktop\djangoProject1_1\venv\lib\site-packages\django\core\handlers\exception.py", line 55, in inner
    response = get_response(request)
  File "C:\Users\Lex\Desktop\djangoProject1_1\venv\lib\site-packages\django\core\handlers\base.py", line 197, in _get_response
    response = wrapped_callback(request, *callback_args, **callback_kwargs)
  File "C:\Users\Lex\Desktop\djangoProject1_1\Django_Project_1\myapp_1\views.py", line 37, in client_order_date
    order_month = Order.objects.get(date_added_order=today.month)
  File "C:\Users\Lex\Desktop\djangoProject1_1\venv\lib\site-packages\django\db\models\manager.py", line 87, in manager_method
    return getattr(self.get_queryset(), name)(*args, **kwargs)
  File "C:\Users\Lex\Desktop\djangoProject1_1\venv\lib\site-packages\django\db\models\query.py", line 623, in get
    clone = self._chain() if self.query.combinator else self.filter(*args, **kwargs)
  File "C:\Users\Lex\Desktop\djangoProject1_1\venv\lib\site-packages\django\db\models\query.py", line 1436, in filter
    return self._filter_or_exclude(False, args, kwargs)
  File "C:\Users\Lex\Desktop\djangoProject1_1\venv\lib\site-packages\django\db\models\query.py", line 1454, in _filter_or_exclude
    clone._filter_or_exclude_inplace(negate, args, kwargs)
  File "C:\Users\Lex\Desktop\djangoProject1_1\venv\lib\site-packages\django\db\models\query.py", line 1461, in _filter_or_exclude_inplace
    self._query.add_q(Q(*args, **kwargs))
  File "C:\Users\Lex\Desktop\djangoProject1_1\venv\lib\site-packages\django\db\models\sql\query.py", line 1545, in add_q
    clause, _ = self._add_q(q_object, self.used_aliases)
  File "C:\Users\Lex\Desktop\djangoProject1_1\venv\lib\site-packages\django\db\models\sql\query.py", line 1576, in _add_q
    child_clause, needed_inner = self.build_filter(
  File "C:\Users\Lex\Desktop\djangoProject1_1\venv\lib\site-packages\django\db\models\sql\query.py", line 1491, in build_filter
    condition = self.build_lookup(lookups, col, value)
  File "C:\Users\Lex\Desktop\djangoProject1_1\venv\lib\site-packages\django\db\models\sql\query.py", line 1318, in build_lookup
    lookup = lookup_class(lhs, rhs)
  File "C:\Users\Lex\Desktop\djangoProject1_1\venv\lib\site-packages\django\db\models\lookups.py", line 27, in __init__
    self.rhs = self.get_prep_lookup()
  File "C:\Users\Lex\Desktop\djangoProject1_1\venv\lib\site-packages\django\db\models\lookups.py", line 341, in get_prep_lookup
    return super().get_prep_lookup()
  File "C:\Users\Lex\Desktop\djangoProject1_1\venv\lib\site-packages\django\db\models\lookups.py", line 85, in get_prep_lookup
    return self.lhs.output_field.get_prep_value(self.rhs)
  File "C:\Users\Lex\Desktop\djangoProject1_1\venv\lib\site-packages\django\db\models\fields\__init__.py", line 1585, in get_prep_value
    value = super().get_prep_value(value)
  File "C:\Users\Lex\Desktop\djangoProject1_1\venv\lib\site-packages\django\db\models\fields\__init__.py", line 1464, in get_prep_value
    return self.to_python(value)
  File "C:\Users\Lex\Desktop\djangoProject1_1\venv\lib\site-packages\django\db\models\fields\__init__.py", line 1546, in to_python
    parsed = parse_datetime(value)
  File "C:\Users\Lex\Desktop\djangoProject1_1\venv\lib\site-packages\django\utils\dateparse.py", line 114, in parse_datetime
    return datetime.datetime.fromisoformat(value)
TypeError: fromisoformat: argument must be str
"GET /order_date/ HTTP/1.1" 500 140891
Internal Server Error: /order_date/
Traceback (most recent call last):
  File "C:\Users\Lex\Desktop\djangoProject1_1\venv\lib\site-packages\django\core\handlers\exception.py", line 55, in inner
    response = get_response(request)
  File "C:\Users\Lex\Desktop\djangoProject1_1\venv\lib\site-packages\django\core\handlers\base.py", line 197, in _get_response
    response = wrapped_callback(request, *callback_args, **callback_kwargs)
  File "C:\Users\Lex\Desktop\djangoProject1_1\Django_Project_1\myapp_1\views.py", line 37, in client_order_date
    order_month = Order.objects.get(date_added_order=today.month)
  File "C:\Users\Lex\Desktop\djangoProject1_1\venv\lib\site-packages\django\db\models\manager.py", line 87, in manager_method
    return getattr(self.get_queryset(), name)(*args, **kwargs)
  File "C:\Users\Lex\Desktop\djangoProject1_1\venv\lib\site-packages\django\db\models\query.py", line 623, in get
    clone = self._chain() if self.query.combinator else self.filter(*args, **kwargs)
  File "C:\Users\Lex\Desktop\djangoProject1_1\venv\lib\site-packages\django\db\models\query.py", line 1436, in filter
    return self._filter_or_exclude(False, args, kwargs)
  File "C:\Users\Lex\Desktop\djangoProject1_1\venv\lib\site-packages\django\db\models\query.py", line 1454, in _filter_or_exclude
    clone._filter_or_exclude_inplace(negate, args, kwargs)
  File "C:\Users\Lex\Desktop\djangoProject1_1\venv\lib\site-packages\django\db\models\query.py", line 1461, in _filter_or_exclude_inplace
    self._query.add_q(Q(*args, **kwargs))
  File "C:\Users\Lex\Desktop\djangoProject1_1\venv\lib\site-packages\django\db\models\sql\query.py", line 1545, in add_q
    clause, _ = self._add_q(q_object, self.used_aliases)
  File "C:\Users\Lex\Desktop\djangoProject1_1\venv\lib\site-packages\django\db\models\sql\query.py", line 1576, in _add_q
    child_clause, needed_inner = self.build_filter(
  File "C:\Users\Lex\Desktop\djangoProject1_1\venv\lib\site-packages\django\db\models\sql\query.py", line 1491, in build_filter
    condition = self.build_lookup(lookups, col, value)
  File "C:\Users\Lex\Desktop\djangoProject1_1\venv\lib\site-packages\django\db\models\sql\query.py", line 1318, in build_lookup
    lookup = lookup_class(lhs, rhs)
  File "C:\Users\Lex\Desktop\djangoProject1_1\venv\lib\site-packages\django\db\models\lookups.py", line 27, in __init__
    self.rhs = self.get_prep_lookup()
  File "C:\Users\Lex\Desktop\djangoProject1_1\venv\lib\site-packages\django\db\models\lookups.py", line 341, in get_prep_lookup
    return super().get_prep_lookup()
  File "C:\Users\Lex\Desktop\djangoProject1_1\venv\lib\site-packages\django\db\models\lookups.py", line 85, in get_prep_lookup
    return self.lhs.output_field.get_prep_value(self.rhs)
  File "C:\Users\Lex\Desktop\djangoProject1_1\venv\lib\site-packages\django\db\models\fields\__init__.py", line 1585, in get_prep_value
    value = super().get_prep_value(value)
  File "C:\Users\Lex\Desktop\djangoProject1_1\venv\lib\site-packages\django\db\models\fields\__init__.py", line 1464, in get_prep_value
    return self.to_python(value)
  File "C:\Users\Lex\Desktop\djangoProject1_1\venv\lib\site-packages\django\db\models\fields\__init__.py", line 1546, in to_python
    parsed = parse_datetime(value)
  File "C:\Users\Lex\Desktop\djangoProject1_1\venv\lib\site-packages\django\utils\dateparse.py", line 114, in parse_datetime
    return datetime.datetime.fromisoformat(value)
TypeError: fromisoformat: argument must be str
"GET /order_date/ HTTP/1.1" 500 140891
Internal Server Error: /order_date/
Traceback (most recent call last):
  File "C:\Users\Lex\Desktop\djangoProject1_1\venv\lib\site-packages\django\core\handlers\exception.py", line 55, in inner
    response = get_response(request)
  File "C:\Users\Lex\Desktop\djangoProject1_1\venv\lib\site-packages\django\core\handlers\base.py", line 197, in _get_response
    response = wrapped_callback(request, *callback_args, **callback_kwargs)
  File "C:\Users\Lex\Desktop\djangoProject1_1\Django_Project_1\myapp_1\views.py", line 37, in client_order_date
    order_month = Order.objects.get(date_added_order=today.month)
  File "C:\Users\Lex\Desktop\djangoProject1_1\venv\lib\site-packages\django\db\models\manager.py", line 87, in manager_method
    return getattr(self.get_queryset(), name)(*args, **kwargs)
  File "C:\Users\Lex\Desktop\djangoProject1_1\venv\lib\site-packages\django\db\models\query.py", line 623, in get
    clone = self._chain() if self.query.combinator else self.filter(*args, **kwargs)
  File "C:\Users\Lex\Desktop\djangoProject1_1\venv\lib\site-packages\django\db\models\query.py", line 1436, in filter
    return self._filter_or_exclude(False, args, kwargs)
  File "C:\Users\Lex\Desktop\djangoProject1_1\venv\lib\site-packages\django\db\models\query.py", line 1454, in _filter_or_exclude
    clone._filter_or_exclude_inplace(negate, args, kwargs)
  File "C:\Users\Lex\Desktop\djangoProject1_1\venv\lib\site-packages\django\db\models\query.py", line 1461, in _filter_or_exclude_inplace
    self._query.add_q(Q(*args, **kwargs))
  File "C:\Users\Lex\Desktop\djangoProject1_1\venv\lib\site-packages\django\db\models\sql\query.py", line 1545, in add_q
    clause, _ = self._add_q(q_object, self.used_aliases)
  File "C:\Users\Lex\Desktop\djangoProject1_1\venv\lib\site-packages\django\db\models\sql\query.py", line 1576, in _add_q
    child_clause, needed_inner = self.build_filter(
  File "C:\Users\Lex\Desktop\djangoProject1_1\venv\lib\site-packages\django\db\models\sql\query.py", line 1491, in build_filter
    condition = self.build_lookup(lookups, col, value)
  File "C:\Users\Lex\Desktop\djangoProject1_1\venv\lib\site-packages\django\db\models\sql\query.py", line 1318, in build_lookup
    lookup = lookup_class(lhs, rhs)
  File "C:\Users\Lex\Desktop\djangoProject1_1\venv\lib\site-packages\django\db\models\lookups.py", line 27, in __init__
    self.rhs = self.get_prep_lookup()
  File "C:\Users\Lex\Desktop\djangoProject1_1\venv\lib\site-packages\django\db\models\lookups.py", line 341, in get_prep_lookup
    return super().get_prep_lookup()
  File "C:\Users\Lex\Desktop\djangoProject1_1\venv\lib\site-packages\django\db\models\lookups.py", line 85, in get_prep_lookup
    return self.lhs.output_field.get_prep_value(self.rhs)
  File "C:\Users\Lex\Desktop\djangoProject1_1\venv\lib\site-packages\django\db\models\fields\__init__.py", line 1585, in get_prep_value
    value = super().get_prep_value(value)
  File "C:\Users\Lex\Desktop\djangoProject1_1\venv\lib\site-packages\django\db\models\fields\__init__.py", line 1464, in get_prep_value
    return self.to_python(value)
  File "C:\Users\Lex\Desktop\djangoProject1_1\venv\lib\site-packages\django\db\models\fields\__init__.py", line 1546, in to_python
    parsed = parse_datetime(value)
  File "C:\Users\Lex\Desktop\djangoProject1_1\venv\lib\site-packages\django\utils\dateparse.py", line 114, in parse_datetime
    return datetime.datetime.fromisoformat(value)
TypeError: fromisoformat: argument must be str
"GET /order_date/ HTTP/1.1" 500 140891
Watching for file changes with StatReloader
Страница index вызвана 2023-09-03 01:09:36.737799
"GET / HTTP/1.1" 200 8057
Internal Server Error: /order_date/
Traceback (most recent call last):
  File "C:\Users\Lex\Desktop\djangoProject1_1\venv\lib\site-packages\django\core\handlers\exception.py", line 55, in inner
    response = get_response(request)
  File "C:\Users\Lex\Desktop\djangoProject1_1\venv\lib\site-packages\django\core\handlers\base.py", line 197, in _get_response
    response = wrapped_callback(request, *callback_args, **callback_kwargs)
  File "C:\Users\Lex\Desktop\djangoProject1_1\Django_Project_1\myapp_1\views.py", line 37, in client_order_date
    order_month = Order.objects.get(date_added_order=today.month)
  File "C:\Users\Lex\Desktop\djangoProject1_1\venv\lib\site-packages\django\db\models\manager.py", line 87, in manager_method
    return getattr(self.get_queryset(), name)(*args, **kwargs)
  File "C:\Users\Lex\Desktop\djangoProject1_1\venv\lib\site-packages\django\db\models\query.py", line 623, in get
    clone = self._chain() if self.query.combinator else self.filter(*args, **kwargs)
  File "C:\Users\Lex\Desktop\djangoProject1_1\venv\lib\site-packages\django\db\models\query.py", line 1436, in filter
    return self._filter_or_exclude(False, args, kwargs)
  File "C:\Users\Lex\Desktop\djangoProject1_1\venv\lib\site-packages\django\db\models\query.py", line 1454, in _filter_or_exclude
    clone._filter_or_exclude_inplace(negate, args, kwargs)
  File "C:\Users\Lex\Desktop\djangoProject1_1\venv\lib\site-packages\django\db\models\query.py", line 1461, in _filter_or_exclude_inplace
    self._query.add_q(Q(*args, **kwargs))
  File "C:\Users\Lex\Desktop\djangoProject1_1\venv\lib\site-packages\django\db\models\sql\query.py", line 1545, in add_q
    clause, _ = self._add_q(q_object, self.used_aliases)
  File "C:\Users\Lex\Desktop\djangoProject1_1\venv\lib\site-packages\django\db\models\sql\query.py", line 1576, in _add_q
    child_clause, needed_inner = self.build_filter(
  File "C:\Users\Lex\Desktop\djangoProject1_1\venv\lib\site-packages\django\db\models\sql\query.py", line 1491, in build_filter
    condition = self.build_lookup(lookups, col, value)
  File "C:\Users\Lex\Desktop\djangoProject1_1\venv\lib\site-packages\django\db\models\sql\query.py", line 1318, in build_lookup
    lookup = lookup_class(lhs, rhs)
  File "C:\Users\Lex\Desktop\djangoProject1_1\venv\lib\site-packages\django\db\models\lookups.py", line 27, in __init__
    self.rhs = self.get_prep_lookup()
  File "C:\Users\Lex\Desktop\djangoProject1_1\venv\lib\site-packages\django\db\models\lookups.py", line 341, in get_prep_lookup
    return super().get_prep_lookup()
  File "C:\Users\Lex\Desktop\djangoProject1_1\venv\lib\site-packages\django\db\models\lookups.py", line 85, in get_prep_lookup
    return self.lhs.output_field.get_prep_value(self.rhs)
  File "C:\Users\Lex\Desktop\djangoProject1_1\venv\lib\site-packages\django\db\models\fields\__init__.py", line 1585, in get_prep_value
    value = super().get_prep_value(value)
  File "C:\Users\Lex\Desktop\djangoProject1_1\venv\lib\site-packages\django\db\models\fields\__init__.py", line 1464, in get_prep_value
    return self.to_python(value)
  File "C:\Users\Lex\Desktop\djangoProject1_1\venv\lib\site-packages\django\db\models\fields\__init__.py", line 1546, in to_python
    parsed = parse_datetime(value)
  File "C:\Users\Lex\Desktop\djangoProject1_1\venv\lib\site-packages\django\utils\dateparse.py", line 114, in parse_datetime
    return datetime.datetime.fromisoformat(value)
TypeError: fromisoformat: argument must be str
"GET /order_date/ HTTP/1.1" 500 140891
Watching for file changes with StatReloader
Страница index вызвана 2023-09-03 01:16:20.677398
"GET / HTTP/1.1" 200 8057
Internal Server Error: /order_date/
Traceback (most recent call last):
  File "C:\Users\Lex\Desktop\djangoProject1_1\venv\lib\site-packages\django\core\handlers\exception.py", line 55, in inner
    response = get_response(request)
  File "C:\Users\Lex\Desktop\djangoProject1_1\venv\lib\site-packages\django\core\handlers\base.py", line 197, in _get_response
    response = wrapped_callback(request, *callback_args, **callback_kwargs)
  File "C:\Users\Lex\Desktop\djangoProject1_1\Django_Project_1\myapp_1\views.py", line 37, in client_order_date
    order_month = Order.objects.get(date_added_order=today.month)
  File "C:\Users\Lex\Desktop\djangoProject1_1\venv\lib\site-packages\django\db\models\manager.py", line 87, in manager_method
    return getattr(self.get_queryset(), name)(*args, **kwargs)
  File "C:\Users\Lex\Desktop\djangoProject1_1\venv\lib\site-packages\django\db\models\query.py", line 623, in get
    clone = self._chain() if self.query.combinator else self.filter(*args, **kwargs)
  File "C:\Users\Lex\Desktop\djangoProject1_1\venv\lib\site-packages\django\db\models\query.py", line 1436, in filter
    return self._filter_or_exclude(False, args, kwargs)
  File "C:\Users\Lex\Desktop\djangoProject1_1\venv\lib\site-packages\django\db\models\query.py", line 1454, in _filter_or_exclude
    clone._filter_or_exclude_inplace(negate, args, kwargs)
  File "C:\Users\Lex\Desktop\djangoProject1_1\venv\lib\site-packages\django\db\models\query.py", line 1461, in _filter_or_exclude_inplace
    self._query.add_q(Q(*args, **kwargs))
  File "C:\Users\Lex\Desktop\djangoProject1_1\venv\lib\site-packages\django\db\models\sql\query.py", line 1545, in add_q
    clause, _ = self._add_q(q_object, self.used_aliases)
  File "C:\Users\Lex\Desktop\djangoProject1_1\venv\lib\site-packages\django\db\models\sql\query.py", line 1576, in _add_q
    child_clause, needed_inner = self.build_filter(
  File "C:\Users\Lex\Desktop\djangoProject1_1\venv\lib\site-packages\django\db\models\sql\query.py", line 1491, in build_filter
    condition = self.build_lookup(lookups, col, value)
  File "C:\Users\Lex\Desktop\djangoProject1_1\venv\lib\site-packages\django\db\models\sql\query.py", line 1318, in build_lookup
    lookup = lookup_class(lhs, rhs)
  File "C:\Users\Lex\Desktop\djangoProject1_1\venv\lib\site-packages\django\db\models\lookups.py", line 27, in __init__
    self.rhs = self.get_prep_lookup()
  File "C:\Users\Lex\Desktop\djangoProject1_1\venv\lib\site-packages\django\db\models\lookups.py", line 341, in get_prep_lookup
    return super().get_prep_lookup()
  File "C:\Users\Lex\Desktop\djangoProject1_1\venv\lib\site-packages\django\db\models\lookups.py", line 85, in get_prep_lookup
    return self.lhs.output_field.get_prep_value(self.rhs)
  File "C:\Users\Lex\Desktop\djangoProject1_1\venv\lib\site-packages\django\db\models\fields\__init__.py", line 1585, in get_prep_value
    value = super().get_prep_value(value)
  File "C:\Users\Lex\Desktop\djangoProject1_1\venv\lib\site-packages\django\db\models\fields\__init__.py", line 1464, in get_prep_value
    return self.to_python(value)
  File "C:\Users\Lex\Desktop\djangoProject1_1\venv\lib\site-packages\django\db\models\fields\__init__.py", line 1546, in to_python
    parsed = parse_datetime(value)
  File "C:\Users\Lex\Desktop\djangoProject1_1\venv\lib\site-packages\django\utils\dateparse.py", line 114, in parse_datetime
    return datetime.datetime.fromisoformat(value)
TypeError: fromisoformat: argument must be str
"GET /order_date/ HTTP/1.1" 500 140891
C:\Users\Lex\Desktop\djangoProject1_1\Django_Project_1\myapp_1\models.py changed, reloading.
Watching for file changes with StatReloader
Страница index вызвана 2023-09-03 01:17:48.581807
"GET / HTTP/1.1" 200 8057
Internal Server Error: /order_date/
Traceback (most recent call last):
  File "C:\Users\Lex\Desktop\djangoProject1_1\venv\lib\site-packages\django\core\handlers\exception.py", line 55, in inner
    response = get_response(request)
  File "C:\Users\Lex\Desktop\djangoProject1_1\venv\lib\site-packages\django\core\handlers\base.py", line 197, in _get_response
    response = wrapped_callback(request, *callback_args, **callback_kwargs)
  File "C:\Users\Lex\Desktop\djangoProject1_1\Django_Project_1\myapp_1\views.py", line 37, in client_order_date
    order_month = Order.objects.get(date_added_order=today.month)
  File "C:\Users\Lex\Desktop\djangoProject1_1\venv\lib\site-packages\django\db\models\manager.py", line 87, in manager_method
    return getattr(self.get_queryset(), name)(*args, **kwargs)
  File "C:\Users\Lex\Desktop\djangoProject1_1\venv\lib\site-packages\django\db\models\query.py", line 623, in get
    clone = self._chain() if self.query.combinator else self.filter(*args, **kwargs)
  File "C:\Users\Lex\Desktop\djangoProject1_1\venv\lib\site-packages\django\db\models\query.py", line 1436, in filter
    return self._filter_or_exclude(False, args, kwargs)
  File "C:\Users\Lex\Desktop\djangoProject1_1\venv\lib\site-packages\django\db\models\query.py", line 1454, in _filter_or_exclude
    clone._filter_or_exclude_inplace(negate, args, kwargs)
  File "C:\Users\Lex\Desktop\djangoProject1_1\venv\lib\site-packages\django\db\models\query.py", line 1461, in _filter_or_exclude_inplace
    self._query.add_q(Q(*args, **kwargs))
  File "C:\Users\Lex\Desktop\djangoProject1_1\venv\lib\site-packages\django\db\models\sql\query.py", line 1545, in add_q
    clause, _ = self._add_q(q_object, self.used_aliases)
  File "C:\Users\Lex\Desktop\djangoProject1_1\venv\lib\site-packages\django\db\models\sql\query.py", line 1576, in _add_q
    child_clause, needed_inner = self.build_filter(
  File "C:\Users\Lex\Desktop\djangoProject1_1\venv\lib\site-packages\django\db\models\sql\query.py", line 1491, in build_filter
    condition = self.build_lookup(lookups, col, value)
  File "C:\Users\Lex\Desktop\djangoProject1_1\venv\lib\site-packages\django\db\models\sql\query.py", line 1318, in build_lookup
    lookup = lookup_class(lhs, rhs)
  File "C:\Users\Lex\Desktop\djangoProject1_1\venv\lib\site-packages\django\db\models\lookups.py", line 27, in __init__
    self.rhs = self.get_prep_lookup()
  File "C:\Users\Lex\Desktop\djangoProject1_1\venv\lib\site-packages\django\db\models\lookups.py", line 341, in get_prep_lookup
    return super().get_prep_lookup()
  File "C:\Users\Lex\Desktop\djangoProject1_1\venv\lib\site-packages\django\db\models\lookups.py", line 85, in get_prep_lookup
    return self.lhs.output_field.get_prep_value(self.rhs)
  File "C:\Users\Lex\Desktop\djangoProject1_1\venv\lib\site-packages\django\db\models\fields\__init__.py", line 1585, in get_prep_value
    value = super().get_prep_value(value)
  File "C:\Users\Lex\Desktop\djangoProject1_1\venv\lib\site-packages\django\db\models\fields\__init__.py", line 1464, in get_prep_value
    return self.to_python(value)
  File "C:\Users\Lex\Desktop\djangoProject1_1\venv\lib\site-packages\django\db\models\fields\__init__.py", line 1546, in to_python
    parsed = parse_datetime(value)
  File "C:\Users\Lex\Desktop\djangoProject1_1\venv\lib\site-packages\django\utils\dateparse.py", line 114, in parse_datetime
    return datetime.datetime.fromisoformat(value)
TypeError: fromisoformat: argument must be str
"GET /order_date/ HTTP/1.1" 500 140891
C:\Users\Lex\Desktop\djangoProject1_1\Django_Project_1\myapp_1\models.py changed, reloading.
Watching for file changes with StatReloader
Страница index вызвана 2023-09-03 01:18:45.364710
"GET / HTTP/1.1" 200 8057
Internal Server Error: /order_date/
Traceback (most recent call last):
  File "C:\Users\Lex\Desktop\djangoProject1_1\venv\lib\site-packages\django\core\handlers\exception.py", line 55, in inner
    response = get_response(request)
  File "C:\Users\Lex\Desktop\djangoProject1_1\venv\lib\site-packages\django\core\handlers\base.py", line 197, in _get_response
    response = wrapped_callback(request, *callback_args, **callback_kwargs)
  File "C:\Users\Lex\Desktop\djangoProject1_1\Django_Project_1\myapp_1\views.py", line 37, in client_order_date
    order_month = Order.objects.get(date_added_order=today.month)
  File "C:\Users\Lex\Desktop\djangoProject1_1\venv\lib\site-packages\django\db\models\manager.py", line 87, in manager_method
    return getattr(self.get_queryset(), name)(*args, **kwargs)
  File "C:\Users\Lex\Desktop\djangoProject1_1\venv\lib\site-packages\django\db\models\query.py", line 623, in get
    clone = self._chain() if self.query.combinator else self.filter(*args, **kwargs)
  File "C:\Users\Lex\Desktop\djangoProject1_1\venv\lib\site-packages\django\db\models\query.py", line 1436, in filter
    return self._filter_or_exclude(False, args, kwargs)
  File "C:\Users\Lex\Desktop\djangoProject1_1\venv\lib\site-packages\django\db\models\query.py", line 1454, in _filter_or_exclude
    clone._filter_or_exclude_inplace(negate, args, kwargs)
  File "C:\Users\Lex\Desktop\djangoProject1_1\venv\lib\site-packages\django\db\models\query.py", line 1461, in _filter_or_exclude_inplace
    self._query.add_q(Q(*args, **kwargs))
  File "C:\Users\Lex\Desktop\djangoProject1_1\venv\lib\site-packages\django\db\models\sql\query.py", line 1545, in add_q
    clause, _ = self._add_q(q_object, self.used_aliases)
  File "C:\Users\Lex\Desktop\djangoProject1_1\venv\lib\site-packages\django\db\models\sql\query.py", line 1576, in _add_q
    child_clause, needed_inner = self.build_filter(
  File "C:\Users\Lex\Desktop\djangoProject1_1\venv\lib\site-packages\django\db\models\sql\query.py", line 1491, in build_filter
    condition = self.build_lookup(lookups, col, value)
  File "C:\Users\Lex\Desktop\djangoProject1_1\venv\lib\site-packages\django\db\models\sql\query.py", line 1318, in build_lookup
    lookup = lookup_class(lhs, rhs)
  File "C:\Users\Lex\Desktop\djangoProject1_1\venv\lib\site-packages\django\db\models\lookups.py", line 27, in __init__
    self.rhs = self.get_prep_lookup()
  File "C:\Users\Lex\Desktop\djangoProject1_1\venv\lib\site-packages\django\db\models\lookups.py", line 341, in get_prep_lookup
    return super().get_prep_lookup()
  File "C:\Users\Lex\Desktop\djangoProject1_1\venv\lib\site-packages\django\db\models\lookups.py", line 85, in get_prep_lookup
    return self.lhs.output_field.get_prep_value(self.rhs)
  File "C:\Users\Lex\Desktop\djangoProject1_1\venv\lib\site-packages\django\db\models\fields\__init__.py", line 1585, in get_prep_value
    value = super().get_prep_value(value)
  File "C:\Users\Lex\Desktop\djangoProject1_1\venv\lib\site-packages\django\db\models\fields\__init__.py", line 1464, in get_prep_value
    return self.to_python(value)
  File "C:\Users\Lex\Desktop\djangoProject1_1\venv\lib\site-packages\django\db\models\fields\__init__.py", line 1546, in to_python
    parsed = parse_datetime(value)
  File "C:\Users\Lex\Desktop\djangoProject1_1\venv\lib\site-packages\django\utils\dateparse.py", line 114, in parse_datetime
    return datetime.datetime.fromisoformat(value)
TypeError: fromisoformat: argument must be str
"GET /order_date/ HTTP/1.1" 500 162395
C:\Users\Lex\Desktop\djangoProject1_1\Django_Project_1\myapp_1\models.py changed, reloading.
Watching for file changes with StatReloader
Страница index вызвана 2023-09-03 01:19:31.160044
"GET / HTTP/1.1" 200 8057
Internal Server Error: /order_date/
Traceback (most recent call last):
  File "C:\Users\Lex\Desktop\djangoProject1_1\venv\lib\site-packages\django\core\handlers\exception.py", line 55, in inner
    response = get_response(request)
  File "C:\Users\Lex\Desktop\djangoProject1_1\venv\lib\site-packages\django\core\handlers\base.py", line 197, in _get_response
    response = wrapped_callback(request, *callback_args, **callback_kwargs)
  File "C:\Users\Lex\Desktop\djangoProject1_1\Django_Project_1\myapp_1\views.py", line 37, in client_order_date
    order_month = Order.objects.get(date_added_order=today.month)
  File "C:\Users\Lex\Desktop\djangoProject1_1\venv\lib\site-packages\django\db\models\manager.py", line 87, in manager_method
    return getattr(self.get_queryset(), name)(*args, **kwargs)
  File "C:\Users\Lex\Desktop\djangoProject1_1\venv\lib\site-packages\django\db\models\query.py", line 623, in get
    clone = self._chain() if self.query.combinator else self.filter(*args, **kwargs)
  File "C:\Users\Lex\Desktop\djangoProject1_1\venv\lib\site-packages\django\db\models\query.py", line 1436, in filter
    return self._filter_or_exclude(False, args, kwargs)
  File "C:\Users\Lex\Desktop\djangoProject1_1\venv\lib\site-packages\django\db\models\query.py", line 1454, in _filter_or_exclude
    clone._filter_or_exclude_inplace(negate, args, kwargs)
  File "C:\Users\Lex\Desktop\djangoProject1_1\venv\lib\site-packages\django\db\models\query.py", line 1461, in _filter_or_exclude_inplace
    self._query.add_q(Q(*args, **kwargs))
  File "C:\Users\Lex\Desktop\djangoProject1_1\venv\lib\site-packages\django\db\models\sql\query.py", line 1545, in add_q
    clause, _ = self._add_q(q_object, self.used_aliases)
  File "C:\Users\Lex\Desktop\djangoProject1_1\venv\lib\site-packages\django\db\models\sql\query.py", line 1576, in _add_q
    child_clause, needed_inner = self.build_filter(
  File "C:\Users\Lex\Desktop\djangoProject1_1\venv\lib\site-packages\django\db\models\sql\query.py", line 1491, in build_filter
    condition = self.build_lookup(lookups, col, value)
  File "C:\Users\Lex\Desktop\djangoProject1_1\venv\lib\site-packages\django\db\models\sql\query.py", line 1318, in build_lookup
    lookup = lookup_class(lhs, rhs)
  File "C:\Users\Lex\Desktop\djangoProject1_1\venv\lib\site-packages\django\db\models\lookups.py", line 27, in __init__
    self.rhs = self.get_prep_lookup()
  File "C:\Users\Lex\Desktop\djangoProject1_1\venv\lib\site-packages\django\db\models\lookups.py", line 341, in get_prep_lookup
    return super().get_prep_lookup()
  File "C:\Users\Lex\Desktop\djangoProject1_1\venv\lib\site-packages\django\db\models\lookups.py", line 85, in get_prep_lookup
    return self.lhs.output_field.get_prep_value(self.rhs)
  File "C:\Users\Lex\Desktop\djangoProject1_1\venv\lib\site-packages\django\db\models\fields\__init__.py", line 1585, in get_prep_value
    value = super().get_prep_value(value)
  File "C:\Users\Lex\Desktop\djangoProject1_1\venv\lib\site-packages\django\db\models\fields\__init__.py", line 1464, in get_prep_value
    return self.to_python(value)
  File "C:\Users\Lex\Desktop\djangoProject1_1\venv\lib\site-packages\django\db\models\fields\__init__.py", line 1546, in to_python
    parsed = parse_datetime(value)
  File "C:\Users\Lex\Desktop\djangoProject1_1\venv\lib\site-packages\django\utils\dateparse.py", line 114, in parse_datetime
    return datetime.datetime.fromisoformat(value)
TypeError: fromisoformat: argument must be str
"GET /order_date/ HTTP/1.1" 500 162395
C:\Users\Lex\Desktop\djangoProject1_1\Django_Project_1\myapp_1\views.py changed, reloading.
Watching for file changes with StatReloader
Страница index вызвана 2023-09-03 01:21:45.013947
"GET / HTTP/1.1" 200 8057
Internal Server Error: /order_date/
Traceback (most recent call last):
  File "C:\Users\Lex\Desktop\djangoProject1_1\venv\lib\site-packages\django\core\handlers\exception.py", line 55, in inner
    response = get_response(request)
  File "C:\Users\Lex\Desktop\djangoProject1_1\venv\lib\site-packages\django\core\handlers\base.py", line 197, in _get_response
    response = wrapped_callback(request, *callback_args, **callback_kwargs)
  File "C:\Users\Lex\Desktop\djangoProject1_1\Django_Project_1\myapp_1\views.py", line 37, in client_order_date
    order_month = Order.objects.get(date_added_order=in_30_days)
  File "C:\Users\Lex\Desktop\djangoProject1_1\venv\lib\site-packages\django\db\models\manager.py", line 87, in manager_method
    return getattr(self.get_queryset(), name)(*args, **kwargs)
  File "C:\Users\Lex\Desktop\djangoProject1_1\venv\lib\site-packages\django\db\models\query.py", line 623, in get
    clone = self._chain() if self.query.combinator else self.filter(*args, **kwargs)
  File "C:\Users\Lex\Desktop\djangoProject1_1\venv\lib\site-packages\django\db\models\query.py", line 1436, in filter
    return self._filter_or_exclude(False, args, kwargs)
  File "C:\Users\Lex\Desktop\djangoProject1_1\venv\lib\site-packages\django\db\models\query.py", line 1454, in _filter_or_exclude
    clone._filter_or_exclude_inplace(negate, args, kwargs)
  File "C:\Users\Lex\Desktop\djangoProject1_1\venv\lib\site-packages\django\db\models\query.py", line 1461, in _filter_or_exclude_inplace
    self._query.add_q(Q(*args, **kwargs))
  File "C:\Users\Lex\Desktop\djangoProject1_1\venv\lib\site-packages\django\db\models\sql\query.py", line 1545, in add_q
    clause, _ = self._add_q(q_object, self.used_aliases)
  File "C:\Users\Lex\Desktop\djangoProject1_1\venv\lib\site-packages\django\db\models\sql\query.py", line 1576, in _add_q
    child_clause, needed_inner = self.build_filter(
  File "C:\Users\Lex\Desktop\djangoProject1_1\venv\lib\site-packages\django\db\models\sql\query.py", line 1491, in build_filter
    condition = self.build_lookup(lookups, col, value)
  File "C:\Users\Lex\Desktop\djangoProject1_1\venv\lib\site-packages\django\db\models\sql\query.py", line 1318, in build_lookup
    lookup = lookup_class(lhs, rhs)
  File "C:\Users\Lex\Desktop\djangoProject1_1\venv\lib\site-packages\django\db\models\lookups.py", line 27, in __init__
    self.rhs = self.get_prep_lookup()
  File "C:\Users\Lex\Desktop\djangoProject1_1\venv\lib\site-packages\django\db\models\lookups.py", line 341, in get_prep_lookup
    return super().get_prep_lookup()
  File "C:\Users\Lex\Desktop\djangoProject1_1\venv\lib\site-packages\django\db\models\lookups.py", line 85, in get_prep_lookup
    return self.lhs.output_field.get_prep_value(self.rhs)
  File "C:\Users\Lex\Desktop\djangoProject1_1\venv\lib\site-packages\django\db\models\fields\__init__.py", line 1585, in get_prep_value
    value = super().get_prep_value(value)
  File "C:\Users\Lex\Desktop\djangoProject1_1\venv\lib\site-packages\django\db\models\fields\__init__.py", line 1464, in get_prep_value
    return self.to_python(value)
  File "C:\Users\Lex\Desktop\djangoProject1_1\venv\lib\site-packages\django\db\models\fields\__init__.py", line 1546, in to_python
    parsed = parse_datetime(value)
  File "C:\Users\Lex\Desktop\djangoProject1_1\venv\lib\site-packages\django\utils\dateparse.py", line 114, in parse_datetime
    return datetime.datetime.fromisoformat(value)
TypeError: fromisoformat: argument must be str
"GET /order_date/ HTTP/1.1" 500 163305
C:\Users\Lex\Desktop\djangoProject1_1\Django_Project_1\myapp_1\views.py changed, reloading.
Watching for file changes with StatReloader
C:\Users\Lex\Desktop\djangoProject1_1\Django_Project_1\myapp_1\models.py changed, reloading.
Watching for file changes with StatReloader
Watching for file changes with StatReloader
Страница index вызвана 2023-09-03 01:43:20.547411
"GET / HTTP/1.1" 200 8057
Internal Server Error: /order_date/
Traceback (most recent call last):
  File "C:\Users\Lex\Desktop\djangoProject1_1\venv\lib\site-packages\django\core\handlers\exception.py", line 55, in inner
    response = get_response(request)
  File "C:\Users\Lex\Desktop\djangoProject1_1\venv\lib\site-packages\django\core\handlers\base.py", line 197, in _get_response
    response = wrapped_callback(request, *callback_args, **callback_kwargs)
  File "C:\Users\Lex\Desktop\djangoProject1_1\Django_Project_1\myapp_1\views.py", line 44, in client_order_date
    if item in temp_orders:
TypeError: argument of type 'datetime.datetime' is not iterable
"GET /order_date/ HTTP/1.1" 500 74125
C:\Users\Lex\Desktop\djangoProject1_1\Django_Project_1\myapp_1\views.py changed, reloading.
Watching for file changes with StatReloader
C:\Users\Lex\Desktop\djangoProject1_1\Django_Project_1\myapp_1\views.py changed, reloading.
Watching for file changes with StatReloader
C:\Users\Lex\Desktop\djangoProject1_1\Django_Project_1\myapp_1\views.py changed, reloading.
Watching for file changes with StatReloader
Internal Server Error: /order_date/
Traceback (most recent call last):
  File "C:\Users\Lex\Desktop\djangoProject1_1\venv\lib\site-packages\django\core\handlers\exception.py", line 55, in inner
    response = get_response(request)
  File "C:\Users\Lex\Desktop\djangoProject1_1\venv\lib\site-packages\django\core\handlers\base.py", line 197, in _get_response
    response = wrapped_callback(request, *callback_args, **callback_kwargs)
  File "C:\Users\Lex\Desktop\djangoProject1_1\Django_Project_1\myapp_1\views.py", line 45, in client_order_date
    if item in temp_orders:
TypeError: argument of type 'datetime.datetime' is not iterable
"GET /order_date/ HTTP/1.1" 500 74147
C:\Users\Lex\Desktop\djangoProject1_1\Django_Project_1\myapp_1\views.py changed, reloading.
Watching for file changes with StatReloader
C:\Users\Lex\Desktop\djangoProject1_1\Django_Project_1\myapp_1\views.py changed, reloading.
Watching for file changes with StatReloader
Internal Server Error: /order_date/
Traceback (most recent call last):
  File "C:\Users\Lex\Desktop\djangoProject1_1\venv\lib\site-packages\django\core\handlers\exception.py", line 55, in inner
    response = get_response(request)
  File "C:\Users\Lex\Desktop\djangoProject1_1\venv\lib\site-packages\django\core\handlers\base.py", line 197, in _get_response
    response = wrapped_callback(request, *callback_args, **callback_kwargs)
  File "C:\Users\Lex\Desktop\djangoProject1_1\Django_Project_1\myapp_1\views.py", line 43, in client_order_date
    orders30 = Order.objects.get(date_added_order__in=temp_orders)
  File "C:\Users\Lex\Desktop\djangoProject1_1\venv\lib\site-packages\django\db\models\manager.py", line 87, in manager_method
    return getattr(self.get_queryset(), name)(*args, **kwargs)
  File "C:\Users\Lex\Desktop\djangoProject1_1\venv\lib\site-packages\django\db\models\query.py", line 623, in get
    clone = self._chain() if self.query.combinator else self.filter(*args, **kwargs)
  File "C:\Users\Lex\Desktop\djangoProject1_1\venv\lib\site-packages\django\db\models\query.py", line 1436, in filter
    return self._filter_or_exclude(False, args, kwargs)
  File "C:\Users\Lex\Desktop\djangoProject1_1\venv\lib\site-packages\django\db\models\query.py", line 1454, in _filter_or_exclude
    clone._filter_or_exclude_inplace(negate, args, kwargs)
  File "C:\Users\Lex\Desktop\djangoProject1_1\venv\lib\site-packages\django\db\models\query.py", line 1461, in _filter_or_exclude_inplace
    self._query.add_q(Q(*args, **kwargs))
  File "C:\Users\Lex\Desktop\djangoProject1_1\venv\lib\site-packages\django\db\models\sql\query.py", line 1545, in add_q
    clause, _ = self._add_q(q_object, self.used_aliases)
  File "C:\Users\Lex\Desktop\djangoProject1_1\venv\lib\site-packages\django\db\models\sql\query.py", line 1576, in _add_q
    child_clause, needed_inner = self.build_filter(
  File "C:\Users\Lex\Desktop\djangoProject1_1\venv\lib\site-packages\django\db\models\sql\query.py", line 1491, in build_filter
    condition = self.build_lookup(lookups, col, value)
  File "C:\Users\Lex\Desktop\djangoProject1_1\venv\lib\site-packages\django\db\models\sql\query.py", line 1318, in build_lookup
    lookup = lookup_class(lhs, rhs)
  File "C:\Users\Lex\Desktop\djangoProject1_1\venv\lib\site-packages\django\db\models\lookups.py", line 27, in __init__
    self.rhs = self.get_prep_lookup()
  File "C:\Users\Lex\Desktop\djangoProject1_1\venv\lib\site-packages\django\db\models\lookups.py", line 426, in get_prep_lookup
    return super().get_prep_lookup()
  File "C:\Users\Lex\Desktop\djangoProject1_1\venv\lib\site-packages\django\db\models\lookups.py", line 270, in get_prep_lookup
    for rhs_value in self.rhs:
TypeError: 'datetime.datetime' object is not iterable
"GET /order_date/ HTTP/1.1" 500 148753
C:\Users\Lex\Desktop\djangoProject1_1\Django_Project_1\myapp_1\views.py changed, reloading.
Watching for file changes with StatReloader
Internal Server Error: /order_date/
Traceback (most recent call last):
  File "C:\Users\Lex\Desktop\djangoProject1_1\venv\lib\site-packages\django\core\handlers\exception.py", line 55, in inner
    response = get_response(request)
  File "C:\Users\Lex\Desktop\djangoProject1_1\venv\lib\site-packages\django\core\handlers\base.py", line 197, in _get_response
    response = wrapped_callback(request, *callback_args, **callback_kwargs)
  File "C:\Users\Lex\Desktop\djangoProject1_1\Django_Project_1\myapp_1\views.py", line 43, in client_order_date
    orders30 = Order.objects.get(date_added_order__in=temp_orders)
  File "C:\Users\Lex\Desktop\djangoProject1_1\venv\lib\site-packages\django\db\models\manager.py", line 87, in manager_method
    return getattr(self.get_queryset(), name)(*args, **kwargs)
  File "C:\Users\Lex\Desktop\djangoProject1_1\venv\lib\site-packages\django\db\models\query.py", line 623, in get
    clone = self._chain() if self.query.combinator else self.filter(*args, **kwargs)
  File "C:\Users\Lex\Desktop\djangoProject1_1\venv\lib\site-packages\django\db\models\query.py", line 1436, in filter
    return self._filter_or_exclude(False, args, kwargs)
  File "C:\Users\Lex\Desktop\djangoProject1_1\venv\lib\site-packages\django\db\models\query.py", line 1454, in _filter_or_exclude
    clone._filter_or_exclude_inplace(negate, args, kwargs)
  File "C:\Users\Lex\Desktop\djangoProject1_1\venv\lib\site-packages\django\db\models\query.py", line 1461, in _filter_or_exclude_inplace
    self._query.add_q(Q(*args, **kwargs))
  File "C:\Users\Lex\Desktop\djangoProject1_1\venv\lib\site-packages\django\db\models\sql\query.py", line 1545, in add_q
    clause, _ = self._add_q(q_object, self.used_aliases)
  File "C:\Users\Lex\Desktop\djangoProject1_1\venv\lib\site-packages\django\db\models\sql\query.py", line 1576, in _add_q
    child_clause, needed_inner = self.build_filter(
  File "C:\Users\Lex\Desktop\djangoProject1_1\venv\lib\site-packages\django\db\models\sql\query.py", line 1491, in build_filter
    condition = self.build_lookup(lookups, col, value)
  File "C:\Users\Lex\Desktop\djangoProject1_1\venv\lib\site-packages\django\db\models\sql\query.py", line 1318, in build_lookup
    lookup = lookup_class(lhs, rhs)
  File "C:\Users\Lex\Desktop\djangoProject1_1\venv\lib\site-packages\django\db\models\lookups.py", line 27, in __init__
    self.rhs = self.get_prep_lookup()
  File "C:\Users\Lex\Desktop\djangoProject1_1\venv\lib\site-packages\django\db\models\lookups.py", line 426, in get_prep_lookup
    return super().get_prep_lookup()
  File "C:\Users\Lex\Desktop\djangoProject1_1\venv\lib\site-packages\django\db\models\lookups.py", line 270, in get_prep_lookup
    for rhs_value in self.rhs:
TypeError: 'datetime.datetime' object is not iterable
"GET /order_date/ HTTP/1.1" 500 148759
C:\Users\Lex\Desktop\djangoProject1_1\Django_Project_1\myapp_1\views.py changed, reloading.
Watching for file changes with StatReloader
Internal Server Error: /order_date/
Traceback (most recent call last):
  File "C:\Users\Lex\Desktop\djangoProject1_1\venv\lib\site-packages\django\core\handlers\exception.py", line 55, in inner
    response = get_response(request)
  File "C:\Users\Lex\Desktop\djangoProject1_1\venv\lib\site-packages\django\core\handlers\base.py", line 197, in _get_response
    response = wrapped_callback(request, *callback_args, **callback_kwargs)
  File "C:\Users\Lex\Desktop\djangoProject1_1\Django_Project_1\myapp_1\views.py", line 43, in client_order_date
    orders30 = Order.objects.filter(date_added_order__in=temp_orders)
  File "C:\Users\Lex\Desktop\djangoProject1_1\venv\lib\site-packages\django\db\models\manager.py", line 87, in manager_method
    return getattr(self.get_queryset(), name)(*args, **kwargs)
  File "C:\Users\Lex\Desktop\djangoProject1_1\venv\lib\site-packages\django\db\models\query.py", line 1436, in filter
    return self._filter_or_exclude(False, args, kwargs)
  File "C:\Users\Lex\Desktop\djangoProject1_1\venv\lib\site-packages\django\db\models\query.py", line 1454, in _filter_or_exclude
    clone._filter_or_exclude_inplace(negate, args, kwargs)
  File "C:\Users\Lex\Desktop\djangoProject1_1\venv\lib\site-packages\django\db\models\query.py", line 1461, in _filter_or_exclude_inplace
    self._query.add_q(Q(*args, **kwargs))
  File "C:\Users\Lex\Desktop\djangoProject1_1\venv\lib\site-packages\django\db\models\sql\query.py", line 1545, in add_q
    clause, _ = self._add_q(q_object, self.used_aliases)
  File "C:\Users\Lex\Desktop\djangoProject1_1\venv\lib\site-packages\django\db\models\sql\query.py", line 1576, in _add_q
    child_clause, needed_inner = self.build_filter(
  File "C:\Users\Lex\Desktop\djangoProject1_1\venv\lib\site-packages\django\db\models\sql\query.py", line 1491, in build_filter
    condition = self.build_lookup(lookups, col, value)
  File "C:\Users\Lex\Desktop\djangoProject1_1\venv\lib\site-packages\django\db\models\sql\query.py", line 1318, in build_lookup
    lookup = lookup_class(lhs, rhs)
  File "C:\Users\Lex\Desktop\djangoProject1_1\venv\lib\site-packages\django\db\models\lookups.py", line 27, in __init__
    self.rhs = self.get_prep_lookup()
  File "C:\Users\Lex\Desktop\djangoProject1_1\venv\lib\site-packages\django\db\models\lookups.py", line 426, in get_prep_lookup
    return super().get_prep_lookup()
  File "C:\Users\Lex\Desktop\djangoProject1_1\venv\lib\site-packages\django\db\models\lookups.py", line 270, in get_prep_lookup
    for rhs_value in self.rhs:
TypeError: 'datetime.datetime' object is not iterable
"GET /order_date/ HTTP/1.1" 500 140892
Internal Server Error: /order_date/
Traceback (most recent call last):
  File "C:\Users\Lex\Desktop\djangoProject1_1\venv\lib\site-packages\django\core\handlers\exception.py", line 55, in inner
    response = get_response(request)
  File "C:\Users\Lex\Desktop\djangoProject1_1\venv\lib\site-packages\django\core\handlers\base.py", line 197, in _get_response
    response = wrapped_callback(request, *callback_args, **callback_kwargs)
  File "C:\Users\Lex\Desktop\djangoProject1_1\Django_Project_1\myapp_1\views.py", line 43, in client_order_date
    orders30 = Order.objects.filter(date_added_order__in=temp_orders)
  File "C:\Users\Lex\Desktop\djangoProject1_1\venv\lib\site-packages\django\db\models\manager.py", line 87, in manager_method
    return getattr(self.get_queryset(), name)(*args, **kwargs)
  File "C:\Users\Lex\Desktop\djangoProject1_1\venv\lib\site-packages\django\db\models\query.py", line 1436, in filter
    return self._filter_or_exclude(False, args, kwargs)
  File "C:\Users\Lex\Desktop\djangoProject1_1\venv\lib\site-packages\django\db\models\query.py", line 1454, in _filter_or_exclude
    clone._filter_or_exclude_inplace(negate, args, kwargs)
  File "C:\Users\Lex\Desktop\djangoProject1_1\venv\lib\site-packages\django\db\models\query.py", line 1461, in _filter_or_exclude_inplace
    self._query.add_q(Q(*args, **kwargs))
  File "C:\Users\Lex\Desktop\djangoProject1_1\venv\lib\site-packages\django\db\models\sql\query.py", line 1545, in add_q
    clause, _ = self._add_q(q_object, self.used_aliases)
  File "C:\Users\Lex\Desktop\djangoProject1_1\venv\lib\site-packages\django\db\models\sql\query.py", line 1576, in _add_q
    child_clause, needed_inner = self.build_filter(
  File "C:\Users\Lex\Desktop\djangoProject1_1\venv\lib\site-packages\django\db\models\sql\query.py", line 1491, in build_filter
    condition = self.build_lookup(lookups, col, value)
  File "C:\Users\Lex\Desktop\djangoProject1_1\venv\lib\site-packages\django\db\models\sql\query.py", line 1318, in build_lookup
    lookup = lookup_class(lhs, rhs)
  File "C:\Users\Lex\Desktop\djangoProject1_1\venv\lib\site-packages\django\db\models\lookups.py", line 27, in __init__
    self.rhs = self.get_prep_lookup()
  File "C:\Users\Lex\Desktop\djangoProject1_1\venv\lib\site-packages\django\db\models\lookups.py", line 426, in get_prep_lookup
    return super().get_prep_lookup()
  File "C:\Users\Lex\Desktop\djangoProject1_1\venv\lib\site-packages\django\db\models\lookups.py", line 270, in get_prep_lookup
    for rhs_value in self.rhs:
TypeError: 'datetime.datetime' object is not iterable
"GET /order_date/ HTTP/1.1" 500 140907
C:\Users\Lex\Desktop\djangoProject1_1\Django_Project_1\myapp_1\views.py changed, reloading.
Watching for file changes with StatReloader
Internal Server Error: /order_date/
Traceback (most recent call last):
  File "C:\Users\Lex\Desktop\djangoProject1_1\venv\lib\site-packages\django\core\handlers\exception.py", line 55, in inner
    response = get_response(request)
  File "C:\Users\Lex\Desktop\djangoProject1_1\venv\lib\site-packages\django\core\handlers\base.py", line 197, in _get_response
    response = wrapped_callback(request, *callback_args, **callback_kwargs)
  File "C:\Users\Lex\Desktop\djangoProject1_1\Django_Project_1\myapp_1\views.py", line 43, in client_order_date
    orders30 = Order.objects.filter(date_added_order__=temp_orders)
  File "C:\Users\Lex\Desktop\djangoProject1_1\venv\lib\site-packages\django\db\models\manager.py", line 87, in manager_method
    return getattr(self.get_queryset(), name)(*args, **kwargs)
  File "C:\Users\Lex\Desktop\djangoProject1_1\venv\lib\site-packages\django\db\models\query.py", line 1436, in filter
    return self._filter_or_exclude(False, args, kwargs)
  File "C:\Users\Lex\Desktop\djangoProject1_1\venv\lib\site-packages\django\db\models\query.py", line 1454, in _filter_or_exclude
    clone._filter_or_exclude_inplace(negate, args, kwargs)
  File "C:\Users\Lex\Desktop\djangoProject1_1\venv\lib\site-packages\django\db\models\query.py", line 1461, in _filter_or_exclude_inplace
    self._query.add_q(Q(*args, **kwargs))
  File "C:\Users\Lex\Desktop\djangoProject1_1\venv\lib\site-packages\django\db\models\sql\query.py", line 1545, in add_q
    clause, _ = self._add_q(q_object, self.used_aliases)
  File "C:\Users\Lex\Desktop\djangoProject1_1\venv\lib\site-packages\django\db\models\sql\query.py", line 1576, in _add_q
    child_clause, needed_inner = self.build_filter(
  File "C:\Users\Lex\Desktop\djangoProject1_1\venv\lib\site-packages\django\db\models\sql\query.py", line 1491, in build_filter
    condition = self.build_lookup(lookups, col, value)
  File "C:\Users\Lex\Desktop\djangoProject1_1\venv\lib\site-packages\django\db\models\sql\query.py", line 1312, in build_lookup
    lhs = self.try_transform(lhs, lookup_name)
  File "C:\Users\Lex\Desktop\djangoProject1_1\venv\lib\site-packages\django\db\models\sql\query.py", line 1356, in try_transform
    raise FieldError(
django.core.exceptions.FieldError: Unsupported lookup '' for DateTimeField or join on the field not permitted.
"GET /order_date/ HTTP/1.1" 500 133319
C:\Users\Lex\Desktop\djangoProject1_1\Django_Project_1\myapp_1\views.py changed, reloading.
Watching for file changes with StatReloader
"GET /order_date/ HTTP/1.1" 200 11773
C:\Users\Lex\Desktop\djangoProject1_1\Django_Project_1\myapp_1\views.py changed, reloading.
Watching for file changes with StatReloader
C:\Users\Lex\Desktop\djangoProject1_1\Django_Project_1\myapp_1\views.py changed, reloading.
Watching for file changes with StatReloader
"GET /order_date/ HTTP/1.1" 200 15455
"GET /order_date/ HTTP/1.1" 200 15455
"GET /order_date/ HTTP/1.1" 200 15455
"GET /order_date/ HTTP/1.1" 200 15455
"GET /order_date/ HTTP/1.1" 200 15499
"GET /order_date/ HTTP/1.1" 200 15435
C:\Users\Lex\Desktop\djangoProject1_1\Django_Project_1\myapp_1\views.py changed, reloading.
Watching for file changes with StatReloader
C:\Users\Lex\Desktop\djangoProject1_1\Django_Project_1\myapp_1\views.py changed, reloading.
Watching for file changes with StatReloader
"GET /order_date/ HTTP/1.1" 200 19207
Not Found: /myapp_1/order_date/
"GET /myapp_1/order_date/ HTTP/1.1" 404 2648
C:\Users\Lex\Desktop\djangoProject1_1\Django_Project_1\myapp_1\views.py changed, reloading.
Watching for file changes with StatReloader
C:\Users\Lex\Desktop\djangoProject1_1\Django_Project_1\myapp_1\views.py changed, reloading.
Watching for file changes with StatReloader
"GET /order_date/ HTTP/1.1" 200 22984
"GET /order_date/ HTTP/1.1" 200 22985
C:\Users\Lex\Desktop\djangoProject1_1\Django_Project_1\myapp_1\models.py changed, reloading.
Watching for file changes with StatReloader
"GET /order_date/ HTTP/1.1" 200 22919
"GET /order_date/ HTTP/1.1" 200 22919
"GET /order_date/ HTTP/1.1" 200 22919
"GET /order_date/ HTTP/1.1" 200 22919
Watching for file changes with StatReloader
Страница index вызвана 2023-09-03 03:09:51.591057
"GET / HTTP/1.1" 200 8057
"GET /order_date/ HTTP/1.1" 200 22919
"GET /order_date/ HTTP/1.1" 200 22919
"GET /order_date/ HTTP/1.1" 200 22919
"GET /order_date/ HTTP/1.1" 200 22919
"GET /order_date/ HTTP/1.1" 200 22919
"GET /order_date/ HTTP/1.1" 200 22919
"GET /order_date/ HTTP/1.1" 200 22919
"GET /order_date/ HTTP/1.1" 200 22919
Watching for file changes with StatReloader
Страница index вызвана 2023-09-03 03:13:34.517146
"GET / HTTP/1.1" 200 8057
"GET /order_date/ HTTP/1.1" 200 22919
"GET /order_date/ HTTP/1.1" 200 22919
"GET /order_date/ HTTP/1.1" 200 22919
"GET /order_date/ HTTP/1.1" 200 22919
"GET /order_date/ HTTP/1.1" 200 22919
"GET /order_date/ HTTP/1.1" 200 22919
"GET /order_date/ HTTP/1.1" 200 22919
"GET /order_date/ HTTP/1.1" 200 22919
"GET /order_date/ HTTP/1.1" 200 22919
"GET /order_date/ HTTP/1.1" 200 22919
"GET /order_date/ HTTP/1.1" 200 22919
"GET /order_date/ HTTP/1.1" 200 22919
"GET /order_date/ HTTP/1.1" 200 22919
"GET /order_date/ HTTP/1.1" 200 22919
"GET /order_date/ HTTP/1.1" 200 22919
"GET /order_date/ HTTP/1.1" 200 22919
"GET /order_date/ HTTP/1.1" 200 22919
"GET /order_date/ HTTP/1.1" 200 22919
"GET /order_date/ HTTP/1.1" 200 22919
Watching for file changes with StatReloader
Страница index вызвана 2023-09-03 03:20:22.385386
"GET / HTTP/1.1" 200 8057
"GET /order_date/ HTTP/1.1" 200 22919
Watching for file changes with StatReloader
Страница index вызвана 2023-09-03 03:27:26.104988
"GET / HTTP/1.1" 200 8057
"GET /order_date/ HTTP/1.1" 200 22919
Страница index вызвана 2023-09-03 03:28:29.390183
"GET / HTTP/1.1" 200 8057
Страница index вызвана 2023-09-03 03:29:13.141880
"GET / HTTP/1.1" 200 8057
Страница index вызвана 2023-09-03 03:29:13.896797
"GET / HTTP/1.1" 200 8057
Страница index вызвана 2023-09-03 03:29:14.331381
"GET / HTTP/1.1" 200 8057
Страница index вызвана 2023-09-03 03:29:14.590179
"GET / HTTP/1.1" 200 8057
Страница index вызвана 2023-09-03 03:29:14.795272
"GET / HTTP/1.1" 200 8057
Страница index вызвана 2023-09-03 03:29:15.173209
"GET / HTTP/1.1" 200 8057
Страница index вызвана 2023-09-03 03:29:15.415895
"GET / HTTP/1.1" 200 8057
Страница index вызвана 2023-09-03 03:29:15.662002
"GET / HTTP/1.1" 200 8057
Страница index вызвана 2023-09-03 03:29:15.909567
"GET / HTTP/1.1" 200 8057
Страница index вызвана 2023-09-03 03:29:16.153226
"GET / HTTP/1.1" 200 8057
Страница index вызвана 2023-09-03 03:29:16.396890
"GET / HTTP/1.1" 200 8057
"GET /order_date/ HTTP/1.1" 200 22919
"GET /order_date/ HTTP/1.1" 200 22919
"GET /order_date/ HTTP/1.1" 200 22919
"GET /order_date/ HTTP/1.1" 200 22919
"GET /order_date/ HTTP/1.1" 200 22919
"GET /order_date/ HTTP/1.1" 200 22919
"GET /order_date/ HTTP/1.1" 200 22919
"GET /order_date/ HTTP/1.1" 200 22932
Watching for file changes with StatReloader
Страница index вызвана 2023-09-03 03:45:52.043043
"GET / HTTP/1.1" 200 8070
"GET /order_date/ HTTP/1.1" 200 22932
"GET /order_date/ HTTP/1.1" 200 22932
"GET /order_date/ HTTP/1.1" 200 22932
"GET /order_date/ HTTP/1.1" 200 22932
"GET /order_date/ HTTP/1.1" 200 22932
"GET /order_date/ HTTP/1.1" 200 22932
"GET /order_date/ HTTP/1.1" 200 22932
"GET /order_date/ HTTP/1.1" 200 22932
"GET /order_date/ HTTP/1.1" 200 22932
"GET /order_date/ HTTP/1.1" 200 22932
"GET /order_date/ HTTP/1.1" 200 22932
Watching for file changes with StatReloader
"GET /order_date/ HTTP/1.1" 200 22932
"GET /order_date/ HTTP/1.1" 200 22932
"GET /order_date/ HTTP/1.1" 200 22932
"GET /order_date/ HTTP/1.1" 200 22932
"GET /order_date/ HTTP/1.1" 200 22932
"GET /order_date/ HTTP/1.1" 200 22932
"GET /order_date/ HTTP/1.1" 200 22932
"GET /order_date/ HTTP/1.1" 200 22932
"GET /order_date/ HTTP/1.1" 200 22932
"GET /order_date/ HTTP/1.1" 200 22932
"GET /order_date/ HTTP/1.1" 200 22932
Watching for file changes with StatReloader
Страница index вызвана 2023-09-03 03:57:35.205082
"GET / HTTP/1.1" 200 2059
"GET /order_date/ HTTP/1.1" 200 16921
Страница index вызвана 2023-09-03 03:58:48.078479
"GET / HTTP/1.1" 200 2059
Watching for file changes with StatReloader
Страница index вызвана 2023-09-09 22:09:51.385437
"GET / HTTP/1.1" 200 2059
"GET /static/myapp_1/style.css HTTP/1.1" 200 572
Not Found: /favicon.ico
"GET /favicon.ico HTTP/1.1" 404 2798
"GET /add_user HTTP/1.1" 301 0
"GET /add_user/ HTTP/1.1" 200 3029
"POST /add_user/ HTTP/1.1" 200 3161
"POST /add_user/ HTTP/1.1" 200 3161
C:\Users\Lex\Desktop\djangoProject1_1\Django_Project_1\myapp_1\views.py changed, reloading.
Watching for file changes with StatReloader
Watching for file changes with StatReloader
Страница index вызвана 2023-09-09 22:20:19.255463
"GET / HTTP/1.1" 200 2059
"GET /add_user/ HTTP/1.1" 200 3029
Watching for file changes with StatReloader
Страница index вызвана 2023-09-09 22:21:52.739705
"GET / HTTP/1.1" 200 2059
"GET /add_user/ HTTP/1.1" 200 3029
Watching for file changes with StatReloader
Страница index вызвана 2023-09-09 22:22:54.215181
"GET / HTTP/1.1" 200 2059
"GET /add_user/ HTTP/1.1" 200 3029
"POST /add_user/ HTTP/1.1" 200 3161
"POST /add_user/ HTTP/1.1" 200 3162
C:\Users\Lex\Desktop\djangoProject1_1\Django_Project_1\myapp_1\views.py changed, reloading.
Watching for file changes with StatReloader
C:\Users\Lex\Desktop\djangoProject1_1\Django_Project_1\myapp_1\views.py changed, reloading.
Watching for file changes with StatReloader
Watching for file changes with StatReloader
Страница index вызвана 2023-09-09 22:45:54.583624
"GET / HTTP/1.1" 200 2059
"GET /add_user/ HTTP/1.1" 200 3029
"POST /add_user/ HTTP/1.1" 200 3161
Watching for file changes with StatReloader
Страница index вызвана 2023-09-09 22:51:06.345910
"GET / HTTP/1.1" 200 2059
"GET /add_user/ HTTP/1.1" 200 3049
"POST /add_user/ HTTP/1.1" 200 3181
"POST /add_user/ HTTP/1.1" 200 3181
"POST /add_user/ HTTP/1.1" 200 3428
Watching for file changes with StatReloader
Страница index вызвана 2023-09-09 23:05:22.346503
"GET / HTTP/1.1" 200 2059
"GET /add_user/ HTTP/1.1" 200 3296
Internal Server Error: /add_user/
Traceback (most recent call last):
  File "C:\Users\Lex\Desktop\djangoProject1_1\venv\lib\site-packages\django\core\handlers\exception.py", line 55, in inner
    response = get_response(request)
  File "C:\Users\Lex\Desktop\djangoProject1_1\venv\lib\site-packages\django\core\handlers\base.py", line 197, in _get_response
    response = wrapped_callback(request, *callback_args, **callback_kwargs)
  File "C:\Users\Lex\Desktop\djangoProject1_1\Django_Project_1\myapp_1\views.py", line 81, in user_form
    return render(request, 'myapp_1/add_user.html', {'form': form, 'message': message})
UnboundLocalError: local variable 'message' referenced before assignment
"POST /add_user/ HTTP/1.1" 500 71968
C:\Users\Lex\Desktop\djangoProject1_1\Django_Project_1\myapp_1\views.py changed, reloading.
Watching for file changes with StatReloader
Страница index вызвана 2023-09-09 23:07:05.733712
"GET / HTTP/1.1" 200 2059
"GET /add_user/ HTTP/1.1" 200 3296
"POST /add_user/ HTTP/1.1" 200 3427
C:\Users\Lex\Desktop\djangoProject1_1\Django_Project_1\myapp_1\form_user.py changed, reloading.
Watching for file changes with StatReloader
Watching for file changes with StatReloader
Watching for file changes with StatReloader
Страница index вызвана 2023-09-09 23:13:00.517252
"GET / HTTP/1.1" 200 2059
"GET /add_user/ HTTP/1.1" 200 3296
Watching for file changes with StatReloader
Страница index вызвана 2023-09-10 03:34:21.071601
"GET / HTTP/1.1" 200 2059
Not Found: /favicon.ico
"GET /favicon.ico HTTP/1.1" 404 2798
"GET /add_user/ HTTP/1.1" 200 3679
Watching for file changes with StatReloader
Страница index вызвана 2023-09-10 03:38:11.776642
"GET / HTTP/1.1" 200 2059
"GET /add_user/ HTTP/1.1" 200 3387
Internal Server Error: /add_user/
Traceback (most recent call last):
  File "C:\Users\Lex\Desktop\djangoProject1_1\venv\lib\site-packages\django\core\handlers\exception.py", line 55, in inner
    response = get_response(request)
  File "C:\Users\Lex\Desktop\djangoProject1_1\venv\lib\site-packages\django\core\handlers\base.py", line 197, in _get_response
    response = wrapped_callback(request, *callback_args, **callback_kwargs)
  File "C:\Users\Lex\Desktop\djangoProject1_1\Django_Project_1\myapp_1\views.py", line 81, in user_form
    return render(request, 'myapp_1/add_user.html', {'form': form, 'message': message})
UnboundLocalError: local variable 'message' referenced before assignment
"POST /add_user/ HTTP/1.1" 500 72255
C:\Users\Lex\Desktop\djangoProject1_1\Django_Project_1\myapp_1\views.py changed, reloading.
Watching for file changes with StatReloader
Страница index вызвана 2023-09-10 03:42:45.985292
"GET / HTTP/1.1" 200 2059
"GET /add_user/ HTTP/1.1" 200 3387
"POST /add_user/ HTTP/1.1" 200 3541
"POST /add_user/ HTTP/1.1" 200 3541
C:\Users\Lex\Desktop\djangoProject1_1\Django_Project_1\djangoProject_1\settings.py changed, reloading.
Watching for file changes with StatReloader
C:\Users\Lex\Desktop\djangoProject1_1\Django_Project_1\djangoProject_1\settings.py changed, reloading.
Watching for file changes with StatReloader
Watching for file changes with StatReloader
Страница index вызвана 2023-09-10 04:25:17.390524
"GET / HTTP/1.1" 200 2059
Watching for file changes with StatReloader
Страница index вызвана 2023-09-10 04:26:35.023929
"GET / HTTP/1.1" 200 2059
Watching for file changes with StatReloader
Страница index вызвана 2023-09-10 04:45:13.016567
"GET / HTTP/1.1" 200 2059
Not Found: /favicon.ico
"GET /favicon.ico HTTP/1.1" 404 2798
"GET /add_user/ HTTP/1.1" 200 3387
"POST /add_user/ HTTP/1.1" 200 3482
"POST /add_user/ HTTP/1.1" 200 3500
"POST /add_user/ HTTP/1.1" 200 3501
Internal Server Error: /add_user/
Traceback (most recent call last):
  File "C:\Users\Lex\Desktop\djangoProject1_1\venv\lib\site-packages\django\db\utils.py", line 98, in inner
    return func(*args, **kwargs)
sqlite3.OperationalError: database is locked

The above exception was the direct cause of the following exception:

Traceback (most recent call last):
  File "C:\Users\Lex\Desktop\djangoProject1_1\venv\lib\site-packages\django\core\handlers\exception.py", line 55, in inner
    response = get_response(request)
  File "C:\Users\Lex\Desktop\djangoProject1_1\venv\lib\site-packages\django\core\handlers\base.py", line 197, in _get_response
    response = wrapped_callback(request, *callback_args, **callback_kwargs)
  File "C:\Users\Lex\Desktop\djangoProject1_1\Django_Project_1\myapp_1\views.py", line 76, in user_form
    client.save()
  File "C:\Users\Lex\Desktop\djangoProject1_1\venv\lib\site-packages\django\db\models\base.py", line 814, in save
    self.save_base(
  File "C:\Users\Lex\Desktop\djangoProject1_1\venv\lib\site-packages\django\db\models\base.py", line 877, in save_base
    updated = self._save_table(
  File "C:\Users\Lex\Desktop\djangoProject1_1\venv\lib\site-packages\django\db\models\base.py", line 1020, in _save_table
    results = self._do_insert(
  File "C:\Users\Lex\Desktop\djangoProject1_1\venv\lib\site-packages\django\db\models\base.py", line 1061, in _do_insert
    return manager._insert(
  File "C:\Users\Lex\Desktop\djangoProject1_1\venv\lib\site-packages\django\db\models\manager.py", line 87, in manager_method
    return getattr(self.get_queryset(), name)(*args, **kwargs)
  File "C:\Users\Lex\Desktop\djangoProject1_1\venv\lib\site-packages\django\db\models\query.py", line 1805, in _insert
    return query.get_compiler(using=using).execute_sql(returning_fields)
  File "C:\Users\Lex\Desktop\djangoProject1_1\venv\lib\site-packages\django\db\models\sql\compiler.py", line 1833, in execute_sql
    self.connection.ops.fetch_returned_insert_columns(
  File "C:\Users\Lex\Desktop\djangoProject1_1\venv\lib\site-packages\django\db\backends\base\operations.py", line 213, in fetch_returned_insert_columns
    return cursor.fetchone()
  File "C:\Users\Lex\Desktop\djangoProject1_1\venv\lib\site-packages\django\db\utils.py", line 97, in inner
    with self:
  File "C:\Users\Lex\Desktop\djangoProject1_1\venv\lib\site-packages\django\db\utils.py", line 91, in __exit__
    raise dj_exc_value.with_traceback(traceback) from exc_value
  File "C:\Users\Lex\Desktop\djangoProject1_1\venv\lib\site-packages\django\db\utils.py", line 98, in inner
    return func(*args, **kwargs)
django.db.utils.OperationalError: database is locked
"POST /add_user/ HTTP/1.1" 500 137993
Watching for file changes with StatReloader
Страница index вызвана 2023-09-10 04:54:41.716525
"GET / HTTP/1.1" 200 2059
"GET /add_user/ HTTP/1.1" 200 3416
"POST /add_user/ HTTP/1.1" 200 3508
Watching for file changes with StatReloader
Страница index вызвана 2023-09-10 05:01:09.421742
"GET / HTTP/1.1" 200 2059
"GET /add_user/ HTTP/1.1" 200 3416
C:\Users\Lex\Desktop\djangoProject1_1\Django_Project_1\myapp_1\models.py changed, reloading.
Watching for file changes with StatReloader
Страница index вызвана 2023-09-10 05:04:31.910193
"GET / HTTP/1.1" 200 2059
"GET /add_user/ HTTP/1.1" 200 3416
Watching for file changes with StatReloader
Страница index вызвана 2023-09-10 05:08:09.072486
"GET / HTTP/1.1" 200 2059
"GET /add_user/ HTTP/1.1" 200 3416
Watching for file changes with StatReloader
Страница index вызвана 2023-09-10 05:12:02.154594
"GET / HTTP/1.1" 200 2059
"GET /add_user/ HTTP/1.1" 200 3416
"POST /add_user/ HTTP/1.1" 200 3510
Watching for file changes with StatReloader
Страница index вызвана 2023-09-10 06:33:55.462543
"GET / HTTP/1.1" 200 2059
Not Found: /favicon.ico
"GET /favicon.ico HTTP/1.1" 404 2798
"GET /add_user/ HTTP/1.1" 200 3407
Internal Server Error: /add_user/
Traceback (most recent call last):
  File "C:\Users\Lex\Desktop\djangoProject1_1\venv\lib\site-packages\django\core\handlers\exception.py", line 55, in inner
    response = get_response(request)
  File "C:\Users\Lex\Desktop\djangoProject1_1\venv\lib\site-packages\django\core\handlers\base.py", line 197, in _get_response
    response = wrapped_callback(request, *callback_args, **callback_kwargs)
  File "C:\Users\Lex\Desktop\djangoProject1_1\Django_Project_1\myapp_1\views.py", line 75, in user_form
    password=password, user_photo=fs.save(user_photo, user_photo))
  File "C:\Users\Lex\Desktop\djangoProject1_1\venv\lib\site-packages\django\core\files\storage\base.py", line 32, in save
    name = content.name
AttributeError: 'NoneType' object has no attribute 'name'
"POST /add_user/ HTTP/1.1" 500 79057
C:\Users\Lex\Desktop\djangoProject1_1\Django_Project_1\myapp_1\views.py changed, reloading.
Watching for file changes with StatReloader
Страница index вызвана 2023-09-10 06:36:56.825616
"GET / HTTP/1.1" 200 2059
"GET /add_user/ HTTP/1.1" 200 3407
"POST /add_user/ HTTP/1.1" 200 3499
Internal Server Error: /add_user/
Traceback (most recent call last):
  File "C:\Users\Lex\Desktop\djangoProject1_1\venv\lib\site-packages\django\db\utils.py", line 98, in inner
    return func(*args, **kwargs)
sqlite3.OperationalError: database is locked

The above exception was the direct cause of the following exception:

Traceback (most recent call last):
  File "C:\Users\Lex\Desktop\djangoProject1_1\venv\lib\site-packages\django\core\handlers\exception.py", line 55, in inner
    response = get_response(request)
  File "C:\Users\Lex\Desktop\djangoProject1_1\venv\lib\site-packages\django\core\handlers\base.py", line 197, in _get_response
    response = wrapped_callback(request, *callback_args, **callback_kwargs)
  File "C:\Users\Lex\Desktop\djangoProject1_1\Django_Project_1\myapp_1\views.py", line 76, in user_form
    client.save()
  File "C:\Users\Lex\Desktop\djangoProject1_1\venv\lib\site-packages\django\db\models\base.py", line 814, in save
    self.save_base(
  File "C:\Users\Lex\Desktop\djangoProject1_1\venv\lib\site-packages\django\db\models\base.py", line 877, in save_base
    updated = self._save_table(
  File "C:\Users\Lex\Desktop\djangoProject1_1\venv\lib\site-packages\django\db\models\base.py", line 1020, in _save_table
    results = self._do_insert(
  File "C:\Users\Lex\Desktop\djangoProject1_1\venv\lib\site-packages\django\db\models\base.py", line 1061, in _do_insert
    return manager._insert(
  File "C:\Users\Lex\Desktop\djangoProject1_1\venv\lib\site-packages\django\db\models\manager.py", line 87, in manager_method
    return getattr(self.get_queryset(), name)(*args, **kwargs)
  File "C:\Users\Lex\Desktop\djangoProject1_1\venv\lib\site-packages\django\db\models\query.py", line 1805, in _insert
    return query.get_compiler(using=using).execute_sql(returning_fields)
  File "C:\Users\Lex\Desktop\djangoProject1_1\venv\lib\site-packages\django\db\models\sql\compiler.py", line 1833, in execute_sql
    self.connection.ops.fetch_returned_insert_columns(
  File "C:\Users\Lex\Desktop\djangoProject1_1\venv\lib\site-packages\django\db\backends\base\operations.py", line 213, in fetch_returned_insert_columns
    return cursor.fetchone()
  File "C:\Users\Lex\Desktop\djangoProject1_1\venv\lib\site-packages\django\db\utils.py", line 97, in inner
    with self:
  File "C:\Users\Lex\Desktop\djangoProject1_1\venv\lib\site-packages\django\db\utils.py", line 91, in __exit__
    raise dj_exc_value.with_traceback(traceback) from exc_value
  File "C:\Users\Lex\Desktop\djangoProject1_1\venv\lib\site-packages\django\db\utils.py", line 98, in inner
    return func(*args, **kwargs)
django.db.utils.OperationalError: database is locked
"POST /add_user/ HTTP/1.1" 500 138212
"POST /add_user/ HTTP/1.1" 200 3499
"POST /add_user/ HTTP/1.1" 200 3501
Watching for file changes with StatReloader
Страница index вызвана 2023-09-10 06:40:04.890202
"GET / HTTP/1.1" 200 2059
"GET /add_user/ HTTP/1.1" 200 3407
Internal Server Error: /add_user/
Traceback (most recent call last):
  File "C:\Users\Lex\Desktop\djangoProject1_1\venv\lib\site-packages\django\db\backends\utils.py", line 89, in _execute
    return self.cursor.execute(sql, params)
  File "C:\Users\Lex\Desktop\djangoProject1_1\venv\lib\site-packages\django\db\backends\sqlite3\base.py", line 328, in execute
    return super().execute(query, params)
sqlite3.OperationalError: database is locked

The above exception was the direct cause of the following exception:

Traceback (most recent call last):
  File "C:\Users\Lex\Desktop\djangoProject1_1\venv\lib\site-packages\django\core\handlers\exception.py", line 55, in inner
    response = get_response(request)
  File "C:\Users\Lex\Desktop\djangoProject1_1\venv\lib\site-packages\django\core\handlers\base.py", line 197, in _get_response
    response = wrapped_callback(request, *callback_args, **callback_kwargs)
  File "C:\Users\Lex\Desktop\djangoProject1_1\Django_Project_1\myapp_1\views.py", line 76, in user_form
    client.save()
  File "C:\Users\Lex\Desktop\djangoProject1_1\venv\lib\site-packages\django\db\models\base.py", line 814, in save
    self.save_base(
  File "C:\Users\Lex\Desktop\djangoProject1_1\venv\lib\site-packages\django\db\models\base.py", line 877, in save_base
    updated = self._save_table(
  File "C:\Users\Lex\Desktop\djangoProject1_1\venv\lib\site-packages\django\db\models\base.py", line 1020, in _save_table
    results = self._do_insert(
  File "C:\Users\Lex\Desktop\djangoProject1_1\venv\lib\site-packages\django\db\models\base.py", line 1061, in _do_insert
    return manager._insert(
  File "C:\Users\Lex\Desktop\djangoProject1_1\venv\lib\site-packages\django\db\models\manager.py", line 87, in manager_method
    return getattr(self.get_queryset(), name)(*args, **kwargs)
  File "C:\Users\Lex\Desktop\djangoProject1_1\venv\lib\site-packages\django\db\models\query.py", line 1805, in _insert
    return query.get_compiler(using=using).execute_sql(returning_fields)
  File "C:\Users\Lex\Desktop\djangoProject1_1\venv\lib\site-packages\django\db\models\sql\compiler.py", line 1822, in execute_sql
    cursor.execute(sql, params)
  File "C:\Users\Lex\Desktop\djangoProject1_1\venv\lib\site-packages\django\db\backends\utils.py", line 102, in execute
    return super().execute(sql, params)
  File "C:\Users\Lex\Desktop\djangoProject1_1\venv\lib\site-packages\django\db\backends\utils.py", line 67, in execute
    return self._execute_with_wrappers(
  File "C:\Users\Lex\Desktop\djangoProject1_1\venv\lib\site-packages\django\db\backends\utils.py", line 80, in _execute_with_wrappers
    return executor(sql, params, many, context)
  File "C:\Users\Lex\Desktop\djangoProject1_1\venv\lib\site-packages\django\db\backends\utils.py", line 84, in _execute
    with self.db.wrap_database_errors:
  File "C:\Users\Lex\Desktop\djangoProject1_1\venv\lib\site-packages\django\db\utils.py", line 91, in __exit__
    raise dj_exc_value.with_traceback(traceback) from exc_value
  File "C:\Users\Lex\Desktop\djangoProject1_1\venv\lib\site-packages\django\db\backends\utils.py", line 89, in _execute
    return self.cursor.execute(sql, params)
  File "C:\Users\Lex\Desktop\djangoProject1_1\venv\lib\site-packages\django\db\backends\sqlite3\base.py", line 328, in execute
    return super().execute(query, params)
django.db.utils.OperationalError: database is locked
- Broken pipe from ('127.0.0.1', 49855)
Internal Server Error: /add_user/
Traceback (most recent call last):
  File "C:\Users\Lex\Desktop\djangoProject1_1\venv\lib\site-packages\django\db\utils.py", line 98, in inner
    return func(*args, **kwargs)
sqlite3.OperationalError: database is locked

The above exception was the direct cause of the following exception:

Traceback (most recent call last):
  File "C:\Users\Lex\Desktop\djangoProject1_1\venv\lib\site-packages\django\core\handlers\exception.py", line 55, in inner
    response = get_response(request)
  File "C:\Users\Lex\Desktop\djangoProject1_1\venv\lib\site-packages\django\core\handlers\base.py", line 197, in _get_response
    response = wrapped_callback(request, *callback_args, **callback_kwargs)
  File "C:\Users\Lex\Desktop\djangoProject1_1\Django_Project_1\myapp_1\views.py", line 76, in user_form
    client.save()
  File "C:\Users\Lex\Desktop\djangoProject1_1\venv\lib\site-packages\django\db\models\base.py", line 814, in save
    self.save_base(
  File "C:\Users\Lex\Desktop\djangoProject1_1\venv\lib\site-packages\django\db\models\base.py", line 877, in save_base
    updated = self._save_table(
  File "C:\Users\Lex\Desktop\djangoProject1_1\venv\lib\site-packages\django\db\models\base.py", line 1020, in _save_table
    results = self._do_insert(
  File "C:\Users\Lex\Desktop\djangoProject1_1\venv\lib\site-packages\django\db\models\base.py", line 1061, in _do_insert
    return manager._insert(
  File "C:\Users\Lex\Desktop\djangoProject1_1\venv\lib\site-packages\django\db\models\manager.py", line 87, in manager_method
    return getattr(self.get_queryset(), name)(*args, **kwargs)
  File "C:\Users\Lex\Desktop\djangoProject1_1\venv\lib\site-packages\django\db\models\query.py", line 1805, in _insert
    return query.get_compiler(using=using).execute_sql(returning_fields)
  File "C:\Users\Lex\Desktop\djangoProject1_1\venv\lib\site-packages\django\db\models\sql\compiler.py", line 1833, in execute_sql
    self.connection.ops.fetch_returned_insert_columns(
  File "C:\Users\Lex\Desktop\djangoProject1_1\venv\lib\site-packages\django\db\backends\base\operations.py", line 213, in fetch_returned_insert_columns
    return cursor.fetchone()
  File "C:\Users\Lex\Desktop\djangoProject1_1\venv\lib\site-packages\django\db\utils.py", line 97, in inner
    with self:
  File "C:\Users\Lex\Desktop\djangoProject1_1\venv\lib\site-packages\django\db\utils.py", line 91, in __exit__
    raise dj_exc_value.with_traceback(traceback) from exc_value
  File "C:\Users\Lex\Desktop\djangoProject1_1\venv\lib\site-packages\django\db\utils.py", line 98, in inner
    return func(*args, **kwargs)
django.db.utils.OperationalError: database is locked
- Broken pipe from ('127.0.0.1', 49856)
Internal Server Error: /add_user/
Traceback (most recent call last):
  File "C:\Users\Lex\Desktop\djangoProject1_1\venv\lib\site-packages\django\db\backends\utils.py", line 89, in _execute
    return self.cursor.execute(sql, params)
  File "C:\Users\Lex\Desktop\djangoProject1_1\venv\lib\site-packages\django\db\backends\sqlite3\base.py", line 328, in execute
    return super().execute(query, params)
sqlite3.OperationalError: database is locked

The above exception was the direct cause of the following exception:

Traceback (most recent call last):
  File "C:\Users\Lex\Desktop\djangoProject1_1\venv\lib\site-packages\django\core\handlers\exception.py", line 55, in inner
    response = get_response(request)
  File "C:\Users\Lex\Desktop\djangoProject1_1\venv\lib\site-packages\django\core\handlers\base.py", line 197, in _get_response
    response = wrapped_callback(request, *callback_args, **callback_kwargs)
  File "C:\Users\Lex\Desktop\djangoProject1_1\Django_Project_1\myapp_1\views.py", line 76, in user_form
    client.save()
  File "C:\Users\Lex\Desktop\djangoProject1_1\venv\lib\site-packages\django\db\models\base.py", line 814, in save
    self.save_base(
  File "C:\Users\Lex\Desktop\djangoProject1_1\venv\lib\site-packages\django\db\models\base.py", line 877, in save_base
    updated = self._save_table(
  File "C:\Users\Lex\Desktop\djangoProject1_1\venv\lib\site-packages\django\db\models\base.py", line 1020, in _save_table
    results = self._do_insert(
  File "C:\Users\Lex\Desktop\djangoProject1_1\venv\lib\site-packages\django\db\models\base.py", line 1061, in _do_insert
    return manager._insert(
  File "C:\Users\Lex\Desktop\djangoProject1_1\venv\lib\site-packages\django\db\models\manager.py", line 87, in manager_method
    return getattr(self.get_queryset(), name)(*args, **kwargs)
  File "C:\Users\Lex\Desktop\djangoProject1_1\venv\lib\site-packages\django\db\models\query.py", line 1805, in _insert
    return query.get_compiler(using=using).execute_sql(returning_fields)
  File "C:\Users\Lex\Desktop\djangoProject1_1\venv\lib\site-packages\django\db\models\sql\compiler.py", line 1822, in execute_sql
    cursor.execute(sql, params)
  File "C:\Users\Lex\Desktop\djangoProject1_1\venv\lib\site-packages\django\db\backends\utils.py", line 102, in execute
    return super().execute(sql, params)
  File "C:\Users\Lex\Desktop\djangoProject1_1\venv\lib\site-packages\django\db\backends\utils.py", line 67, in execute
    return self._execute_with_wrappers(
  File "C:\Users\Lex\Desktop\djangoProject1_1\venv\lib\site-packages\django\db\backends\utils.py", line 80, in _execute_with_wrappers
    return executor(sql, params, many, context)
  File "C:\Users\Lex\Desktop\djangoProject1_1\venv\lib\site-packages\django\db\backends\utils.py", line 84, in _execute
    with self.db.wrap_database_errors:
  File "C:\Users\Lex\Desktop\djangoProject1_1\venv\lib\site-packages\django\db\utils.py", line 91, in __exit__
    raise dj_exc_value.with_traceback(traceback) from exc_value
  File "C:\Users\Lex\Desktop\djangoProject1_1\venv\lib\site-packages\django\db\backends\utils.py", line 89, in _execute
    return self.cursor.execute(sql, params)
  File "C:\Users\Lex\Desktop\djangoProject1_1\venv\lib\site-packages\django\db\backends\sqlite3\base.py", line 328, in execute
    return super().execute(query, params)
django.db.utils.OperationalError: database is locked
Internal Server Error: /add_user/
Traceback (most recent call last):
  File "C:\Users\Lex\Desktop\djangoProject1_1\venv\lib\site-packages\django\db\backends\utils.py", line 89, in _execute
    return self.cursor.execute(sql, params)
  File "C:\Users\Lex\Desktop\djangoProject1_1\venv\lib\site-packages\django\db\backends\sqlite3\base.py", line 328, in execute
    return super().execute(query, params)
sqlite3.OperationalError: database is locked

The above exception was the direct cause of the following exception:

Traceback (most recent call last):
  File "C:\Users\Lex\Desktop\djangoProject1_1\venv\lib\site-packages\django\core\handlers\exception.py", line 55, in inner
    response = get_response(request)
  File "C:\Users\Lex\Desktop\djangoProject1_1\venv\lib\site-packages\django\core\handlers\base.py", line 197, in _get_response
    response = wrapped_callback(request, *callback_args, **callback_kwargs)
  File "C:\Users\Lex\Desktop\djangoProject1_1\Django_Project_1\myapp_1\views.py", line 76, in user_form
    client.save()
  File "C:\Users\Lex\Desktop\djangoProject1_1\venv\lib\site-packages\django\db\models\base.py", line 814, in save
    self.save_base(
  File "C:\Users\Lex\Desktop\djangoProject1_1\venv\lib\site-packages\django\db\models\base.py", line 877, in save_base
    updated = self._save_table(
  File "C:\Users\Lex\Desktop\djangoProject1_1\venv\lib\site-packages\django\db\models\base.py", line 1020, in _save_table
    results = self._do_insert(
  File "C:\Users\Lex\Desktop\djangoProject1_1\venv\lib\site-packages\django\db\models\base.py", line 1061, in _do_insert
    return manager._insert(
  File "C:\Users\Lex\Desktop\djangoProject1_1\venv\lib\site-packages\django\db\models\manager.py", line 87, in manager_method
    return getattr(self.get_queryset(), name)(*args, **kwargs)
  File "C:\Users\Lex\Desktop\djangoProject1_1\venv\lib\site-packages\django\db\models\query.py", line 1805, in _insert
    return query.get_compiler(using=using).execute_sql(returning_fields)
  File "C:\Users\Lex\Desktop\djangoProject1_1\venv\lib\site-packages\django\db\models\sql\compiler.py", line 1822, in execute_sql
    cursor.execute(sql, params)
  File "C:\Users\Lex\Desktop\djangoProject1_1\venv\lib\site-packages\django\db\backends\utils.py", line 102, in execute
    return super().execute(sql, params)
  File "C:\Users\Lex\Desktop\djangoProject1_1\venv\lib\site-packages\django\db\backends\utils.py", line 67, in execute
    return self._execute_with_wrappers(
  File "C:\Users\Lex\Desktop\djangoProject1_1\venv\lib\site-packages\django\db\backends\utils.py", line 80, in _execute_with_wrappers
    return executor(sql, params, many, context)
  File "C:\Users\Lex\Desktop\djangoProject1_1\venv\lib\site-packages\django\db\backends\utils.py", line 84, in _execute
    with self.db.wrap_database_errors:
  File "C:\Users\Lex\Desktop\djangoProject1_1\venv\lib\site-packages\django\db\utils.py", line 91, in __exit__
    raise dj_exc_value.with_traceback(traceback) from exc_value
  File "C:\Users\Lex\Desktop\djangoProject1_1\venv\lib\site-packages\django\db\backends\utils.py", line 89, in _execute
    return self.cursor.execute(sql, params)
  File "C:\Users\Lex\Desktop\djangoProject1_1\venv\lib\site-packages\django\db\backends\sqlite3\base.py", line 328, in execute
    return super().execute(query, params)
django.db.utils.OperationalError: database is locked
Internal Server Error: /add_user/
Traceback (most recent call last):
  File "C:\Users\Lex\Desktop\djangoProject1_1\venv\lib\site-packages\django\db\utils.py", line 98, in inner
    return func(*args, **kwargs)
sqlite3.OperationalError: database is locked

The above exception was the direct cause of the following exception:

Traceback (most recent call last):
  File "C:\Users\Lex\Desktop\djangoProject1_1\venv\lib\site-packages\django\core\handlers\exception.py", line 55, in inner
    response = get_response(request)
  File "C:\Users\Lex\Desktop\djangoProject1_1\venv\lib\site-packages\django\core\handlers\base.py", line 197, in _get_response
    response = wrapped_callback(request, *callback_args, **callback_kwargs)
  File "C:\Users\Lex\Desktop\djangoProject1_1\Django_Project_1\myapp_1\views.py", line 76, in user_form
    client.save()
  File "C:\Users\Lex\Desktop\djangoProject1_1\venv\lib\site-packages\django\db\models\base.py", line 814, in save
    self.save_base(
  File "C:\Users\Lex\Desktop\djangoProject1_1\venv\lib\site-packages\django\db\models\base.py", line 877, in save_base
    updated = self._save_table(
  File "C:\Users\Lex\Desktop\djangoProject1_1\venv\lib\site-packages\django\db\models\base.py", line 1020, in _save_table
    results = self._do_insert(
  File "C:\Users\Lex\Desktop\djangoProject1_1\venv\lib\site-packages\django\db\models\base.py", line 1061, in _do_insert
    return manager._insert(
  File "C:\Users\Lex\Desktop\djangoProject1_1\venv\lib\site-packages\django\db\models\manager.py", line 87, in manager_method
    return getattr(self.get_queryset(), name)(*args, **kwargs)
  File "C:\Users\Lex\Desktop\djangoProject1_1\venv\lib\site-packages\django\db\models\query.py", line 1805, in _insert
    return query.get_compiler(using=using).execute_sql(returning_fields)
  File "C:\Users\Lex\Desktop\djangoProject1_1\venv\lib\site-packages\django\db\models\sql\compiler.py", line 1833, in execute_sql
    self.connection.ops.fetch_returned_insert_columns(
  File "C:\Users\Lex\Desktop\djangoProject1_1\venv\lib\site-packages\django\db\backends\base\operations.py", line 213, in fetch_returned_insert_columns
    return cursor.fetchone()
  File "C:\Users\Lex\Desktop\djangoProject1_1\venv\lib\site-packages\django\db\utils.py", line 97, in inner
    with self:
  File "C:\Users\Lex\Desktop\djangoProject1_1\venv\lib\site-packages\django\db\utils.py", line 91, in __exit__
    raise dj_exc_value.with_traceback(traceback) from exc_value
  File "C:\Users\Lex\Desktop\djangoProject1_1\venv\lib\site-packages\django\db\utils.py", line 98, in inner
    return func(*args, **kwargs)
django.db.utils.OperationalError: database is locked
- Broken pipe from ('127.0.0.1', 49871)
Internal Server Error: /add_user/
Traceback (most recent call last):
  File "C:\Users\Lex\Desktop\djangoProject1_1\venv\lib\site-packages\django\db\utils.py", line 98, in inner
    return func(*args, **kwargs)
sqlite3.OperationalError: database is locked

The above exception was the direct cause of the following exception:

Traceback (most recent call last):
  File "C:\Users\Lex\Desktop\djangoProject1_1\venv\lib\site-packages\django\core\handlers\exception.py", line 55, in inner
    response = get_response(request)
  File "C:\Users\Lex\Desktop\djangoProject1_1\venv\lib\site-packages\django\core\handlers\base.py", line 197, in _get_response
    response = wrapped_callback(request, *callback_args, **callback_kwargs)
  File "C:\Users\Lex\Desktop\djangoProject1_1\Django_Project_1\myapp_1\views.py", line 76, in user_form
    client.save()
  File "C:\Users\Lex\Desktop\djangoProject1_1\venv\lib\site-packages\django\db\models\base.py", line 814, in save
    self.save_base(
  File "C:\Users\Lex\Desktop\djangoProject1_1\venv\lib\site-packages\django\db\models\base.py", line 877, in save_base
    updated = self._save_table(
  File "C:\Users\Lex\Desktop\djangoProject1_1\venv\lib\site-packages\django\db\models\base.py", line 1020, in _save_table
    results = self._do_insert(
  File "C:\Users\Lex\Desktop\djangoProject1_1\venv\lib\site-packages\django\db\models\base.py", line 1061, in _do_insert
    return manager._insert(
  File "C:\Users\Lex\Desktop\djangoProject1_1\venv\lib\site-packages\django\db\models\manager.py", line 87, in manager_method
    return getattr(self.get_queryset(), name)(*args, **kwargs)
  File "C:\Users\Lex\Desktop\djangoProject1_1\venv\lib\site-packages\django\db\models\query.py", line 1805, in _insert
    return query.get_compiler(using=using).execute_sql(returning_fields)
  File "C:\Users\Lex\Desktop\djangoProject1_1\venv\lib\site-packages\django\db\models\sql\compiler.py", line 1833, in execute_sql
    self.connection.ops.fetch_returned_insert_columns(
  File "C:\Users\Lex\Desktop\djangoProject1_1\venv\lib\site-packages\django\db\backends\base\operations.py", line 213, in fetch_returned_insert_columns
    return cursor.fetchone()
  File "C:\Users\Lex\Desktop\djangoProject1_1\venv\lib\site-packages\django\db\utils.py", line 97, in inner
    with self:
  File "C:\Users\Lex\Desktop\djangoProject1_1\venv\lib\site-packages\django\db\utils.py", line 91, in __exit__
    raise dj_exc_value.with_traceback(traceback) from exc_value
  File "C:\Users\Lex\Desktop\djangoProject1_1\venv\lib\site-packages\django\db\utils.py", line 98, in inner
    return func(*args, **kwargs)
django.db.utils.OperationalError: database is locked
- Broken pipe from ('127.0.0.1', 49869)
Internal Server Error: /add_user/
Traceback (most recent call last):
  File "C:\Users\Lex\Desktop\djangoProject1_1\venv\lib\site-packages\django\db\backends\utils.py", line 89, in _execute
    return self.cursor.execute(sql, params)
  File "C:\Users\Lex\Desktop\djangoProject1_1\venv\lib\site-packages\django\db\backends\sqlite3\base.py", line 328, in execute
    return super().execute(query, params)
sqlite3.OperationalError: database is locked

The above exception was the direct cause of the following exception:

Traceback (most recent call last):
  File "C:\Users\Lex\Desktop\djangoProject1_1\venv\lib\site-packages\django\core\handlers\exception.py", line 55, in inner
    response = get_response(request)
  File "C:\Users\Lex\Desktop\djangoProject1_1\venv\lib\site-packages\django\core\handlers\base.py", line 197, in _get_response
    response = wrapped_callback(request, *callback_args, **callback_kwargs)
  File "C:\Users\Lex\Desktop\djangoProject1_1\Django_Project_1\myapp_1\views.py", line 76, in user_form
    client.save()
  File "C:\Users\Lex\Desktop\djangoProject1_1\venv\lib\site-packages\django\db\models\base.py", line 814, in save
    self.save_base(
  File "C:\Users\Lex\Desktop\djangoProject1_1\venv\lib\site-packages\django\db\models\base.py", line 877, in save_base
    updated = self._save_table(
  File "C:\Users\Lex\Desktop\djangoProject1_1\venv\lib\site-packages\django\db\models\base.py", line 1020, in _save_table
    results = self._do_insert(
  File "C:\Users\Lex\Desktop\djangoProject1_1\venv\lib\site-packages\django\db\models\base.py", line 1061, in _do_insert
    return manager._insert(
  File "C:\Users\Lex\Desktop\djangoProject1_1\venv\lib\site-packages\django\db\models\manager.py", line 87, in manager_method
    return getattr(self.get_queryset(), name)(*args, **kwargs)
  File "C:\Users\Lex\Desktop\djangoProject1_1\venv\lib\site-packages\django\db\models\query.py", line 1805, in _insert
    return query.get_compiler(using=using).execute_sql(returning_fields)
  File "C:\Users\Lex\Desktop\djangoProject1_1\venv\lib\site-packages\django\db\models\sql\compiler.py", line 1822, in execute_sql
    cursor.execute(sql, params)
  File "C:\Users\Lex\Desktop\djangoProject1_1\venv\lib\site-packages\django\db\backends\utils.py", line 102, in execute
    return super().execute(sql, params)
  File "C:\Users\Lex\Desktop\djangoProject1_1\venv\lib\site-packages\django\db\backends\utils.py", line 67, in execute
    return self._execute_with_wrappers(
  File "C:\Users\Lex\Desktop\djangoProject1_1\venv\lib\site-packages\django\db\backends\utils.py", line 80, in _execute_with_wrappers
    return executor(sql, params, many, context)
  File "C:\Users\Lex\Desktop\djangoProject1_1\venv\lib\site-packages\django\db\backends\utils.py", line 84, in _execute
    with self.db.wrap_database_errors:
  File "C:\Users\Lex\Desktop\djangoProject1_1\venv\lib\site-packages\django\db\utils.py", line 91, in __exit__
    raise dj_exc_value.with_traceback(traceback) from exc_value
  File "C:\Users\Lex\Desktop\djangoProject1_1\venv\lib\site-packages\django\db\backends\utils.py", line 89, in _execute
    return self.cursor.execute(sql, params)
  File "C:\Users\Lex\Desktop\djangoProject1_1\venv\lib\site-packages\django\db\backends\sqlite3\base.py", line 328, in execute
    return super().execute(query, params)
django.db.utils.OperationalError: database is locked
Internal Server Error: /add_user/
Traceback (most recent call last):
  File "C:\Users\Lex\Desktop\djangoProject1_1\venv\lib\site-packages\django\db\backends\utils.py", line 89, in _execute
    return self.cursor.execute(sql, params)
  File "C:\Users\Lex\Desktop\djangoProject1_1\venv\lib\site-packages\django\db\backends\sqlite3\base.py", line 328, in execute
    return super().execute(query, params)
sqlite3.OperationalError: database is locked

The above exception was the direct cause of the following exception:

Traceback (most recent call last):
  File "C:\Users\Lex\Desktop\djangoProject1_1\venv\lib\site-packages\django\core\handlers\exception.py", line 55, in inner
    response = get_response(request)
  File "C:\Users\Lex\Desktop\djangoProject1_1\venv\lib\site-packages\django\core\handlers\base.py", line 197, in _get_response
    response = wrapped_callback(request, *callback_args, **callback_kwargs)
  File "C:\Users\Lex\Desktop\djangoProject1_1\Django_Project_1\myapp_1\views.py", line 76, in user_form
    client.save()
  File "C:\Users\Lex\Desktop\djangoProject1_1\venv\lib\site-packages\django\db\models\base.py", line 814, in save
    self.save_base(
  File "C:\Users\Lex\Desktop\djangoProject1_1\venv\lib\site-packages\django\db\models\base.py", line 877, in save_base
    updated = self._save_table(
  File "C:\Users\Lex\Desktop\djangoProject1_1\venv\lib\site-packages\django\db\models\base.py", line 1020, in _save_table
    results = self._do_insert(
  File "C:\Users\Lex\Desktop\djangoProject1_1\venv\lib\site-packages\django\db\models\base.py", line 1061, in _do_insert
    return manager._insert(
  File "C:\Users\Lex\Desktop\djangoProject1_1\venv\lib\site-packages\django\db\models\manager.py", line 87, in manager_method
    return getattr(self.get_queryset(), name)(*args, **kwargs)
  File "C:\Users\Lex\Desktop\djangoProject1_1\venv\lib\site-packages\django\db\models\query.py", line 1805, in _insert
    return query.get_compiler(using=using).execute_sql(returning_fields)
  File "C:\Users\Lex\Desktop\djangoProject1_1\venv\lib\site-packages\django\db\models\sql\compiler.py", line 1822, in execute_sql
    cursor.execute(sql, params)
  File "C:\Users\Lex\Desktop\djangoProject1_1\venv\lib\site-packages\django\db\backends\utils.py", line 102, in execute
    return super().execute(sql, params)
  File "C:\Users\Lex\Desktop\djangoProject1_1\venv\lib\site-packages\django\db\backends\utils.py", line 67, in execute
    return self._execute_with_wrappers(
  File "C:\Users\Lex\Desktop\djangoProject1_1\venv\lib\site-packages\django\db\backends\utils.py", line 80, in _execute_with_wrappers
    return executor(sql, params, many, context)
  File "C:\Users\Lex\Desktop\djangoProject1_1\venv\lib\site-packages\django\db\backends\utils.py", line 84, in _execute
    with self.db.wrap_database_errors:
  File "C:\Users\Lex\Desktop\djangoProject1_1\venv\lib\site-packages\django\db\utils.py", line 91, in __exit__
    raise dj_exc_value.with_traceback(traceback) from exc_value
  File "C:\Users\Lex\Desktop\djangoProject1_1\venv\lib\site-packages\django\db\backends\utils.py", line 89, in _execute
    return self.cursor.execute(sql, params)
  File "C:\Users\Lex\Desktop\djangoProject1_1\venv\lib\site-packages\django\db\backends\sqlite3\base.py", line 328, in execute
    return super().execute(query, params)
django.db.utils.OperationalError: database is locked
- Broken pipe from ('127.0.0.1', 49866)
Internal Server Error: /add_user/
Traceback (most recent call last):
  File "C:\Users\Lex\Desktop\djangoProject1_1\venv\lib\site-packages\django\db\backends\utils.py", line 89, in _execute
    return self.cursor.execute(sql, params)
  File "C:\Users\Lex\Desktop\djangoProject1_1\venv\lib\site-packages\django\db\backends\sqlite3\base.py", line 328, in execute
    return super().execute(query, params)
sqlite3.OperationalError: database is locked

The above exception was the direct cause of the following exception:

Traceback (most recent call last):
  File "C:\Users\Lex\Desktop\djangoProject1_1\venv\lib\site-packages\django\core\handlers\exception.py", line 55, in inner
    response = get_response(request)
  File "C:\Users\Lex\Desktop\djangoProject1_1\venv\lib\site-packages\django\core\handlers\base.py", line 197, in _get_response
    response = wrapped_callback(request, *callback_args, **callback_kwargs)
  File "C:\Users\Lex\Desktop\djangoProject1_1\Django_Project_1\myapp_1\views.py", line 76, in user_form
    client.save()
  File "C:\Users\Lex\Desktop\djangoProject1_1\venv\lib\site-packages\django\db\models\base.py", line 814, in save
    self.save_base(
  File "C:\Users\Lex\Desktop\djangoProject1_1\venv\lib\site-packages\django\db\models\base.py", line 877, in save_base
    updated = self._save_table(
  File "C:\Users\Lex\Desktop\djangoProject1_1\venv\lib\site-packages\django\db\models\base.py", line 1020, in _save_table
    results = self._do_insert(
  File "C:\Users\Lex\Desktop\djangoProject1_1\venv\lib\site-packages\django\db\models\base.py", line 1061, in _do_insert
    return manager._insert(
  File "C:\Users\Lex\Desktop\djangoProject1_1\venv\lib\site-packages\django\db\models\manager.py", line 87, in manager_method
    return getattr(self.get_queryset(), name)(*args, **kwargs)
  File "C:\Users\Lex\Desktop\djangoProject1_1\venv\lib\site-packages\django\db\models\query.py", line 1805, in _insert
    return query.get_compiler(using=using).execute_sql(returning_fields)
  File "C:\Users\Lex\Desktop\djangoProject1_1\venv\lib\site-packages\django\db\models\sql\compiler.py", line 1822, in execute_sql
    cursor.execute(sql, params)
  File "C:\Users\Lex\Desktop\djangoProject1_1\venv\lib\site-packages\django\db\backends\utils.py", line 102, in execute
    return super().execute(sql, params)
  File "C:\Users\Lex\Desktop\djangoProject1_1\venv\lib\site-packages\django\db\backends\utils.py", line 67, in execute
    return self._execute_with_wrappers(
  File "C:\Users\Lex\Desktop\djangoProject1_1\venv\lib\site-packages\django\db\backends\utils.py", line 80, in _execute_with_wrappers
    return executor(sql, params, many, context)
  File "C:\Users\Lex\Desktop\djangoProject1_1\venv\lib\site-packages\django\db\backends\utils.py", line 84, in _execute
    with self.db.wrap_database_errors:
  File "C:\Users\Lex\Desktop\djangoProject1_1\venv\lib\site-packages\django\db\utils.py", line 91, in __exit__
    raise dj_exc_value.with_traceback(traceback) from exc_value
  File "C:\Users\Lex\Desktop\djangoProject1_1\venv\lib\site-packages\django\db\backends\utils.py", line 89, in _execute
    return self.cursor.execute(sql, params)
  File "C:\Users\Lex\Desktop\djangoProject1_1\venv\lib\site-packages\django\db\backends\sqlite3\base.py", line 328, in execute
    return super().execute(query, params)
django.db.utils.OperationalError: database is locked
- Broken pipe from ('127.0.0.1', 49868)
- Broken pipe from ('127.0.0.1', 49867)
- Broken pipe from ('127.0.0.1', 49870)
- Broken pipe from ('127.0.0.1', 49872)
Internal Server Error: /add_user/
Traceback (most recent call last):
  File "C:\Users\Lex\Desktop\djangoProject1_1\venv\lib\site-packages\django\db\utils.py", line 98, in inner
    return func(*args, **kwargs)
sqlite3.OperationalError: database is locked

The above exception was the direct cause of the following exception:

Traceback (most recent call last):
  File "C:\Users\Lex\Desktop\djangoProject1_1\venv\lib\site-packages\django\core\handlers\exception.py", line 55, in inner
    response = get_response(request)
  File "C:\Users\Lex\Desktop\djangoProject1_1\venv\lib\site-packages\django\core\handlers\base.py", line 197, in _get_response
    response = wrapped_callback(request, *callback_args, **callback_kwargs)
  File "C:\Users\Lex\Desktop\djangoProject1_1\Django_Project_1\myapp_1\views.py", line 76, in user_form
    client.save()
  File "C:\Users\Lex\Desktop\djangoProject1_1\venv\lib\site-packages\django\db\models\base.py", line 814, in save
    self.save_base(
  File "C:\Users\Lex\Desktop\djangoProject1_1\venv\lib\site-packages\django\db\models\base.py", line 877, in save_base
    updated = self._save_table(
  File "C:\Users\Lex\Desktop\djangoProject1_1\venv\lib\site-packages\django\db\models\base.py", line 1020, in _save_table
    results = self._do_insert(
  File "C:\Users\Lex\Desktop\djangoProject1_1\venv\lib\site-packages\django\db\models\base.py", line 1061, in _do_insert
    return manager._insert(
  File "C:\Users\Lex\Desktop\djangoProject1_1\venv\lib\site-packages\django\db\models\manager.py", line 87, in manager_method
    return getattr(self.get_queryset(), name)(*args, **kwargs)
  File "C:\Users\Lex\Desktop\djangoProject1_1\venv\lib\site-packages\django\db\models\query.py", line 1805, in _insert
    return query.get_compiler(using=using).execute_sql(returning_fields)
  File "C:\Users\Lex\Desktop\djangoProject1_1\venv\lib\site-packages\django\db\models\sql\compiler.py", line 1833, in execute_sql
    self.connection.ops.fetch_returned_insert_columns(
  File "C:\Users\Lex\Desktop\djangoProject1_1\venv\lib\site-packages\django\db\backends\base\operations.py", line 213, in fetch_returned_insert_columns
    return cursor.fetchone()
  File "C:\Users\Lex\Desktop\djangoProject1_1\venv\lib\site-packages\django\db\utils.py", line 97, in inner
    with self:
  File "C:\Users\Lex\Desktop\djangoProject1_1\venv\lib\site-packages\django\db\utils.py", line 91, in __exit__
    raise dj_exc_value.with_traceback(traceback) from exc_value
  File "C:\Users\Lex\Desktop\djangoProject1_1\venv\lib\site-packages\django\db\utils.py", line 98, in inner
    return func(*args, **kwargs)
django.db.utils.OperationalError: database is locked
"POST /add_user/ HTTP/1.1" 500 138514
"POST /add_user/ HTTP/1.1" 200 3494
Internal Server Error: /add_user/
Traceback (most recent call last):
  File "C:\Users\Lex\Desktop\djangoProject1_1\venv\lib\site-packages\django\db\utils.py", line 98, in inner
    return func(*args, **kwargs)
sqlite3.OperationalError: database is locked

The above exception was the direct cause of the following exception:

Traceback (most recent call last):
  File "C:\Users\Lex\Desktop\djangoProject1_1\venv\lib\site-packages\django\core\handlers\exception.py", line 55, in inner
    response = get_response(request)
  File "C:\Users\Lex\Desktop\djangoProject1_1\venv\lib\site-packages\django\core\handlers\base.py", line 197, in _get_response
    response = wrapped_callback(request, *callback_args, **callback_kwargs)
  File "C:\Users\Lex\Desktop\djangoProject1_1\Django_Project_1\myapp_1\views.py", line 76, in user_form
    client.save()
  File "C:\Users\Lex\Desktop\djangoProject1_1\venv\lib\site-packages\django\db\models\base.py", line 814, in save
    self.save_base(
  File "C:\Users\Lex\Desktop\djangoProject1_1\venv\lib\site-packages\django\db\models\base.py", line 877, in save_base
    updated = self._save_table(
  File "C:\Users\Lex\Desktop\djangoProject1_1\venv\lib\site-packages\django\db\models\base.py", line 1020, in _save_table
    results = self._do_insert(
  File "C:\Users\Lex\Desktop\djangoProject1_1\venv\lib\site-packages\django\db\models\base.py", line 1061, in _do_insert
    return manager._insert(
  File "C:\Users\Lex\Desktop\djangoProject1_1\venv\lib\site-packages\django\db\models\manager.py", line 87, in manager_method
    return getattr(self.get_queryset(), name)(*args, **kwargs)
  File "C:\Users\Lex\Desktop\djangoProject1_1\venv\lib\site-packages\django\db\models\query.py", line 1805, in _insert
    return query.get_compiler(using=using).execute_sql(returning_fields)
  File "C:\Users\Lex\Desktop\djangoProject1_1\venv\lib\site-packages\django\db\models\sql\compiler.py", line 1833, in execute_sql
    self.connection.ops.fetch_returned_insert_columns(
  File "C:\Users\Lex\Desktop\djangoProject1_1\venv\lib\site-packages\django\db\backends\base\operations.py", line 213, in fetch_returned_insert_columns
    return cursor.fetchone()
  File "C:\Users\Lex\Desktop\djangoProject1_1\venv\lib\site-packages\django\db\utils.py", line 97, in inner
    with self:
  File "C:\Users\Lex\Desktop\djangoProject1_1\venv\lib\site-packages\django\db\utils.py", line 91, in __exit__
    raise dj_exc_value.with_traceback(traceback) from exc_value
  File "C:\Users\Lex\Desktop\djangoProject1_1\venv\lib\site-packages\django\db\utils.py", line 98, in inner
    return func(*args, **kwargs)
django.db.utils.OperationalError: database is locked
"POST /add_user/ HTTP/1.1" 500 138691
"POST /add_user/ HTTP/1.1" 200 3494
"POST /add_user/ HTTP/1.1" 200 3498
C:\Users\Lex\Desktop\djangoProject1_1\Django_Project_1\myapp_1\views.py changed, reloading.
Watching for file changes with StatReloader
Страница index вызвана 2023-09-10 06:43:54.220600
"GET / HTTP/1.1" 200 2059
"GET /add_user/ HTTP/1.1" 200 3407
Internal Server Error: /add_user/
Traceback (most recent call last):
  File "C:\Users\Lex\Desktop\djangoProject1_1\venv\lib\site-packages\django\core\handlers\exception.py", line 55, in inner
    response = get_response(request)
  File "C:\Users\Lex\Desktop\djangoProject1_1\venv\lib\site-packages\django\core\handlers\base.py", line 197, in _get_response
    response = wrapped_callback(request, *callback_args, **callback_kwargs)
  File "C:\Users\Lex\Desktop\djangoProject1_1\Django_Project_1\myapp_1\views.py", line 75, in user_form
    password=password, user_photo=fs.save(user_photo, user_photo))
  File "C:\Users\Lex\Desktop\djangoProject1_1\venv\lib\site-packages\django\core\files\storage\base.py", line 32, in save
    name = content.name
AttributeError: 'NoneType' object has no attribute 'name'
"POST /add_user/ HTTP/1.1" 500 79038
Watching for file changes with StatReloader
Страница index вызвана 2023-09-10 06:50:35.941408
"GET / HTTP/1.1" 200 2059
"GET /add_user/ HTTP/1.1" 200 3407
Internal Server Error: /add_user/
Traceback (most recent call last):
  File "C:\Users\Lex\Desktop\djangoProject1_1\venv\lib\site-packages\django\core\handlers\exception.py", line 55, in inner
    response = get_response(request)
  File "C:\Users\Lex\Desktop\djangoProject1_1\venv\lib\site-packages\django\core\handlers\base.py", line 197, in _get_response
    response = wrapped_callback(request, *callback_args, **callback_kwargs)
  File "C:\Users\Lex\Desktop\djangoProject1_1\Django_Project_1\myapp_1\views.py", line 75, in user_form
    password=password, user_photo=fs.save(user_photo, user_photo))
  File "C:\Users\Lex\Desktop\djangoProject1_1\venv\lib\site-packages\django\core\files\storage\base.py", line 32, in save
    name = content.name
AttributeError: 'NoneType' object has no attribute 'name'
"POST /add_user/ HTTP/1.1" 500 79047
Watching for file changes with StatReloader
Страница index вызвана 2023-09-10 07:04:17.629080
"GET / HTTP/1.1" 200 2059
"GET /add_user/ HTTP/1.1" 200 3407
Internal Server Error: /add_user/
Traceback (most recent call last):
  File "C:\Users\Lex\Desktop\djangoProject1_1\venv\lib\site-packages\django\db\utils.py", line 98, in inner
    return func(*args, **kwargs)
sqlite3.OperationalError: database is locked

The above exception was the direct cause of the following exception:

Traceback (most recent call last):
  File "C:\Users\Lex\Desktop\djangoProject1_1\venv\lib\site-packages\django\core\handlers\exception.py", line 55, in inner
    response = get_response(request)
  File "C:\Users\Lex\Desktop\djangoProject1_1\venv\lib\site-packages\django\core\handlers\base.py", line 197, in _get_response
    response = wrapped_callback(request, *callback_args, **callback_kwargs)
  File "C:\Users\Lex\Desktop\djangoProject1_1\Django_Project_1\myapp_1\views.py", line 76, in user_form
    client.save()
  File "C:\Users\Lex\Desktop\djangoProject1_1\venv\lib\site-packages\django\db\models\base.py", line 814, in save
    self.save_base(
  File "C:\Users\Lex\Desktop\djangoProject1_1\venv\lib\site-packages\django\db\models\base.py", line 877, in save_base
    updated = self._save_table(
  File "C:\Users\Lex\Desktop\djangoProject1_1\venv\lib\site-packages\django\db\models\base.py", line 1020, in _save_table
    results = self._do_insert(
  File "C:\Users\Lex\Desktop\djangoProject1_1\venv\lib\site-packages\django\db\models\base.py", line 1061, in _do_insert
    return manager._insert(
  File "C:\Users\Lex\Desktop\djangoProject1_1\venv\lib\site-packages\django\db\models\manager.py", line 87, in manager_method
    return getattr(self.get_queryset(), name)(*args, **kwargs)
  File "C:\Users\Lex\Desktop\djangoProject1_1\venv\lib\site-packages\django\db\models\query.py", line 1805, in _insert
    return query.get_compiler(using=using).execute_sql(returning_fields)
  File "C:\Users\Lex\Desktop\djangoProject1_1\venv\lib\site-packages\django\db\models\sql\compiler.py", line 1833, in execute_sql
    self.connection.ops.fetch_returned_insert_columns(
  File "C:\Users\Lex\Desktop\djangoProject1_1\venv\lib\site-packages\django\db\backends\base\operations.py", line 213, in fetch_returned_insert_columns
    return cursor.fetchone()
  File "C:\Users\Lex\Desktop\djangoProject1_1\venv\lib\site-packages\django\db\utils.py", line 97, in inner
    with self:
  File "C:\Users\Lex\Desktop\djangoProject1_1\venv\lib\site-packages\django\db\utils.py", line 91, in __exit__
    raise dj_exc_value.with_traceback(traceback) from exc_value
  File "C:\Users\Lex\Desktop\djangoProject1_1\venv\lib\site-packages\django\db\utils.py", line 98, in inner
    return func(*args, **kwargs)
django.db.utils.OperationalError: database is locked
Internal Server Error: /add_user/
Traceback (most recent call last):
  File "C:\Users\Lex\Desktop\djangoProject1_1\venv\lib\site-packages\django\db\utils.py", line 98, in inner
    return func(*args, **kwargs)
sqlite3.OperationalError: database is locked

The above exception was the direct cause of the following exception:

Traceback (most recent call last):
  File "C:\Users\Lex\Desktop\djangoProject1_1\venv\lib\site-packages\django\core\handlers\exception.py", line 55, in inner
    response = get_response(request)
  File "C:\Users\Lex\Desktop\djangoProject1_1\venv\lib\site-packages\django\core\handlers\base.py", line 197, in _get_response
    response = wrapped_callback(request, *callback_args, **callback_kwargs)
  File "C:\Users\Lex\Desktop\djangoProject1_1\Django_Project_1\myapp_1\views.py", line 76, in user_form
    client.save()
  File "C:\Users\Lex\Desktop\djangoProject1_1\venv\lib\site-packages\django\db\models\base.py", line 814, in save
    self.save_base(
  File "C:\Users\Lex\Desktop\djangoProject1_1\venv\lib\site-packages\django\db\models\base.py", line 877, in save_base
    updated = self._save_table(
  File "C:\Users\Lex\Desktop\djangoProject1_1\venv\lib\site-packages\django\db\models\base.py", line 1020, in _save_table
    results = self._do_insert(
  File "C:\Users\Lex\Desktop\djangoProject1_1\venv\lib\site-packages\django\db\models\base.py", line 1061, in _do_insert
    return manager._insert(
  File "C:\Users\Lex\Desktop\djangoProject1_1\venv\lib\site-packages\django\db\models\manager.py", line 87, in manager_method
    return getattr(self.get_queryset(), name)(*args, **kwargs)
  File "C:\Users\Lex\Desktop\djangoProject1_1\venv\lib\site-packages\django\db\models\query.py", line 1805, in _insert
    return query.get_compiler(using=using).execute_sql(returning_fields)
  File "C:\Users\Lex\Desktop\djangoProject1_1\venv\lib\site-packages\django\db\models\sql\compiler.py", line 1833, in execute_sql
    self.connection.ops.fetch_returned_insert_columns(
  File "C:\Users\Lex\Desktop\djangoProject1_1\venv\lib\site-packages\django\db\backends\base\operations.py", line 213, in fetch_returned_insert_columns
    return cursor.fetchone()
  File "C:\Users\Lex\Desktop\djangoProject1_1\venv\lib\site-packages\django\db\utils.py", line 97, in inner
    with self:
  File "C:\Users\Lex\Desktop\djangoProject1_1\venv\lib\site-packages\django\db\utils.py", line 91, in __exit__
    raise dj_exc_value.with_traceback(traceback) from exc_value
  File "C:\Users\Lex\Desktop\djangoProject1_1\venv\lib\site-packages\django\db\utils.py", line 98, in inner
    return func(*args, **kwargs)
django.db.utils.OperationalError: database is locked
- Broken pipe from ('127.0.0.1', 50546)
"POST /add_user/ HTTP/1.1" 500 139308
"POST /add_user/ HTTP/1.1" 200 3496
Internal Server Error: /add_user/
Traceback (most recent call last):
  File "C:\Users\Lex\Desktop\djangoProject1_1\venv\lib\site-packages\django\core\handlers\exception.py", line 55, in inner
    response = get_response(request)
  File "C:\Users\Lex\Desktop\djangoProject1_1\venv\lib\site-packages\django\core\handlers\base.py", line 197, in _get_response
    response = wrapped_callback(request, *callback_args, **callback_kwargs)
  File "C:\Users\Lex\Desktop\djangoProject1_1\Django_Project_1\myapp_1\views.py", line 75, in user_form
    password=password, user_photo=fs.save(user_photo, user_photo))
  File "C:\Users\Lex\Desktop\djangoProject1_1\venv\lib\site-packages\django\core\files\storage\base.py", line 32, in save
    name = content.name
AttributeError: 'NoneType' object has no attribute 'name'
"POST /add_user/ HTTP/1.1" 500 79047
Internal Server Error: /add_user/
Traceback (most recent call last):
  File "C:\Users\Lex\Desktop\djangoProject1_1\venv\lib\site-packages\django\db\utils.py", line 98, in inner
    return func(*args, **kwargs)
sqlite3.OperationalError: database is locked

The above exception was the direct cause of the following exception:

Traceback (most recent call last):
  File "C:\Users\Lex\Desktop\djangoProject1_1\venv\lib\site-packages\django\core\handlers\exception.py", line 55, in inner
    response = get_response(request)
  File "C:\Users\Lex\Desktop\djangoProject1_1\venv\lib\site-packages\django\core\handlers\base.py", line 197, in _get_response
    response = wrapped_callback(request, *callback_args, **callback_kwargs)
  File "C:\Users\Lex\Desktop\djangoProject1_1\Django_Project_1\myapp_1\views.py", line 76, in user_form
    client.save()
  File "C:\Users\Lex\Desktop\djangoProject1_1\venv\lib\site-packages\django\db\models\base.py", line 814, in save
    self.save_base(
  File "C:\Users\Lex\Desktop\djangoProject1_1\venv\lib\site-packages\django\db\models\base.py", line 877, in save_base
    updated = self._save_table(
  File "C:\Users\Lex\Desktop\djangoProject1_1\venv\lib\site-packages\django\db\models\base.py", line 1020, in _save_table
    results = self._do_insert(
  File "C:\Users\Lex\Desktop\djangoProject1_1\venv\lib\site-packages\django\db\models\base.py", line 1061, in _do_insert
    return manager._insert(
  File "C:\Users\Lex\Desktop\djangoProject1_1\venv\lib\site-packages\django\db\models\manager.py", line 87, in manager_method
    return getattr(self.get_queryset(), name)(*args, **kwargs)
  File "C:\Users\Lex\Desktop\djangoProject1_1\venv\lib\site-packages\django\db\models\query.py", line 1805, in _insert
    return query.get_compiler(using=using).execute_sql(returning_fields)
  File "C:\Users\Lex\Desktop\djangoProject1_1\venv\lib\site-packages\django\db\models\sql\compiler.py", line 1833, in execute_sql
    self.connection.ops.fetch_returned_insert_columns(
  File "C:\Users\Lex\Desktop\djangoProject1_1\venv\lib\site-packages\django\db\backends\base\operations.py", line 213, in fetch_returned_insert_columns
    return cursor.fetchone()
  File "C:\Users\Lex\Desktop\djangoProject1_1\venv\lib\site-packages\django\db\utils.py", line 97, in inner
    with self:
  File "C:\Users\Lex\Desktop\djangoProject1_1\venv\lib\site-packages\django\db\utils.py", line 91, in __exit__
    raise dj_exc_value.with_traceback(traceback) from exc_value
  File "C:\Users\Lex\Desktop\djangoProject1_1\venv\lib\site-packages\django\db\utils.py", line 98, in inner
    return func(*args, **kwargs)
django.db.utils.OperationalError: database is locked
- Broken pipe from ('127.0.0.1', 50545)
